Workbook
Name estrategia_venda: #REF!
Name respons_propostas: #REF!
Name estrategia_diags: #REF!
Name respons_diags: #REF!
Name status_agendamento: #REF!
Name propostas: #REF!
Name produto_propostas: #REF!
Name Data_agendamento: #REF!
Name Diag_Mês: #REF!
Name prop_dw: #REF!
Name vendas: #REF!
Name proposta_Mês: #REF!
Name data_diag: #REF!
Name vendedor_propostas: #REF!
Name responsavel_vendido: #REF!
Name diags: #REF!
Name valor_propostas: #REF!
Name vendedor_vendido: #REF!
Name estrategia_propostas: #REF!
Name data_propostas: #REF!
Name venda_dw: #REF!
Name estrategia_agendamentos: #REF!
Name respons_agendamentos: #REF!
Name data_proposta: #REF!
Name mes_ganho: #REF!
Name valor_vendido: #REF!
Name Agendamento_Mês: #REF!
Name data_ganho: #REF!
Name data_diags: #REF!
Name data_agendamentos: #REF!
Name mês_ganho: #REF!
Name vendedor_diags: #REF!
Name agendamentos: #REF!

Sheet Dados da Operação
B2: DADOS DA OPERAÇÃO | E2: ESTRATÉGIAS DA OPERAÇÃO
B3: Meta semestre | C3: 25000 | E3: Estratégia | F3: Participação na meta | G3: Meta semestral por estratégia | H3: Meta média mensal por estratégia | I3: Qtdd venda semestral | J3: Qntdd de venda mensal
B4: Alcance atual | C4: x | E4: Ativa | F4: 1 | G4: =C3*F4 -> 25000 | H4: =G4/6 -> 4166.6667 | I4: =G4/$C$5 -> 10 | J4: =I4/6 -> 1.6666667
B5: Ticket médio | C5: 2500 | E5: Passiva | F5: 0 | G5: =C3*F5 -> 0 | H5: =G5/6 -> 0 | I5: =G5/$C$5 -> 0 | J5: =I5/6 -> 0
B6: Quantidade de vendas | C6: =C3/C5 -> 10 | E6: Recuperação | F6: 0 | G6: =C3*F6 -> 0 | H6: =G6/6 -> 0 | I6: =G6/$C$5 -> 0 | J6: =I6/6 -> 0
E7: Expansão | F7: 0 | G7: =C3*F7 -> 0 | H7: =G7/6 -> 0 | I7: =G7/$C$5 -> 0 | J7: =I7/6 -> 0
E8: Total da operação | F8: =SUM(F4:F7) -> 1 | G8: =SUM(G4:G7) -> 25000 | H8: =SUM(H4:H7) -> 4166.6667 | I8: =SUM(I4:I7) -> 10 | J8: x
E10: INVESTIMENTOS NA OPERAÇÃO
E11: O que? | F11: Quando? | G11: Porque?
B24: MÊS 1 – JANEIRO | E24: ESTRATÉGIAS – JANEIRO
B25: Meta Janeiro
E26: Estratégia | F26: Participação na meta | G26: Meta Janeiro por estratégia | H26: Qtdd venda mensal
E27: Ativa | F27: 0 | G27: =C25*F27 -> 0 | H27: =G27/$C$5 -> 0
E28: Passiva | F28: 0 | G28: =C25*F28 -> 0 | H28: =G28/$C$5 -> 0
E29: Recuperação | F29: 0 | G29: =C25*F29 -> 0 | H29: =G29/$C$5 -> 0
E30: Expansão | F30: 0 | G30: =C25*F30 -> 0 | H30: =G30/$C$5 -> 0
E31: Total do mês | F31: =SUM(F27:F30) -> 0 | G31: =SUM(G27:G30) -> 0 | H31: =SUM(H27:H30) -> 0
B33: MÊS 2 – FEVEREIRO | E33: ESTRATÉGIAS – FEVEREIRO
B34: Meta Fevereiro
E35: Estratégia | F35: Participação na meta | G35: Meta Fevereiro por estratégia | H35: Qtdd venda mensal
E36: Ativa | F36: 0 | G36: =C34*F36 -> 0 | H36: =G36/$C$5 -> 0
E37: Passiva | F37: 0 | G37: =C34*F37 -> 0 | H37: =G37/$C$5 -> 0
E38: Recuperação | F38: 0 | G38: =C34*F38 -> 0 | H38: =G38/$C$5 -> 0
E39: Expansão | F39: 0 | G39: =C34*F39 -> 0 | H39: =G39/$C$5 -> 0
E40: Total do mês | F40: =SUM(F36:F39) -> 0 | G40: =SUM(G36:G39) -> 0 | H40: =SUM(H36:H39) -> 0
B42: MÊS 3 – MARÇO | E42: ESTRATÉGIAS – MARÇO
B43: Meta Março
E44: Estratégia | F44: Participação na meta | G44: Meta Março por estratégia | H44: Qtdd venda mensal
E45: Ativa | F45: 0 | G45: =C43*F45 -> 0 | H45: =G45/$C$5 -> 0
E46: Passiva | F46: 0 | G46: =C43*F46 -> 0 | H46: =G46/$C$5 -> 0
E47: Recuperação | F47: 0 | G47: =C43*F47 -> 0 | H47: =G47/$C$5 -> 0
E48: Expansão | F48: 0 | G48: =C43*F48 -> 0 | H48: =G48/$C$5 -> 0
E49: Total do mês | F49: =SUM(F45:F48) -> 0 | G49: =SUM(G45:G48) -> 0 | H49: =SUM(H45:H48) -> 0
B51: MÊS 4 – ABRIL | E51: ESTRATÉGIAS – ABRIL
B52: Meta Abril
E53: Estratégia | F53: Participação na meta | G53: Meta Abril por estratégia | H53: Qtdd venda mensal
E54: Ativa | F54: 0 | G54: =C52*F54 -> 0 | H54: =G54/$C$5 -> 0
E55: Passiva | F55: 0 | G55: =C52*F55 -> 0 | H55: =G55/$C$5 -> 0
E56: Recuperação | F56: 0 | G56: =C52*F56 -> 0 | H56: =G56/$C$5 -> 0
E57: Expansão | F57: 0 | G57: =C52*F57 -> 0 | H57: =G57/$C$5 -> 0
...

Sheet Indicadores e Metas
C1: Obs: Preencha apenas os campos em amarelos, demais campos automatizados
C2: Obs: Preenchimento de alcance deve ser preenchindo nas colunas de Atingidodas semanas.
D4: EXECUÇÃO GERAL | F4: JAN | I4: SEMANA 1 | K4: SEMANA 2 | M4: SEMANA 3 | O4: SEMANA 04 | Q4: FEV | S4: SEMANA 1 | U4: SEMANA 2 | W4: SEMANA 3 | Y4: SEMANA 04 | AA4: MAR | AC4: SEMANA 1 | AE4: SEMANA 2 | AG4: SEMANA 3 | AI4: SEMANA 04 | AK4: ABR | AM4: SEMANA 1 | AO4: SEMANA 2 | AQ4: SEMANA 3 | AS4: SEMANA 04 | AU4: MAI | AW4: SEMANA 1 | AY4: SEMANA 2 | BA4: SEMANA 3 | BC4: SEMANA 04 | BE4: JUN | BG4: SEMANA 1 | BI4: SEMANA 2 | BK4: SEMANA 3 | BM4: SEMANA 04 | BO4: JUL | BQ4: SEMANA 1 | BS4: SEMANA 2 | BU4: SEMANA 3 | BW4: SEMANA 04 | BY4: AGO | CA4: SEMANA 1 | CC4: SEMANA 2 | CE4: SEMANA 3 | CG4: SEMANA 04 | CI4: SET | CK4: SEMANA 1 | CM4: SEMANA 2 | CO4: SEMANA 3 | CQ4: SEMANA 04 | CS4: OUT | CU4: SEMANA 1 | CW4: SEMANA 2 | CY4: SEMANA 3 | DA4: SEMANA 04 | DC4: NOV | DE4: SEMANA 1 | DG4: SEMANA 2 | DI4: SEMANA 3 | DK4: SEMANA 04 | DM4: DEZ | DO4: SEMANA 1 | DQ4: SEMANA 2 | DS4: SEMANA 3 | DU4: SEMANA 04
D5: Atingido | E5: Meta | F5: Atingido | G5: Meta | H5: Farol | I5: Atingido | J5: Meta | K5: Atingido | L5: Meta | M5: Atingido | N5: Meta | O5: Atingido | P5: Meta | Q5: Atingido | R5: Meta | S5: Atingido | T5: Meta | U5: Atingido | V5: Meta | W5: Atingido | X5: Meta | Y5: Atingido | Z5: Meta | AA5: Atingido | AB5: Meta | AC5: Atingido | AD5: Meta | AE5: Atingido | AF5: Meta | AG5: Atingido | AH5: Meta | AI5: Atingido | AJ5: Meta | AK5: Atingido | AL5: Meta | AM5: Atingido | AN5: Meta | AO5: Atingido | AP5: Meta | AQ5: Atingido | AR5: Meta | AS5: Atingido | AT5: Meta | AU5: Atingido | AV5: Meta | AW5: Atingido | AX5: Meta | AY5: Atingido | AZ5: Meta | BA5: Atingido | BB5: Meta | BC5: Atingido | BD5: Meta | BE5: Atingido | BF5: Meta | BG5: Atingido | BH5: Meta | BI5: Atingido | BJ5: Meta | BK5: Atingido | BL5: Meta | BM5: Atingido | BN5: Meta | BO5: Atingido | BP5: Meta | BQ5: Atingido | BR5: Meta | BS5: Atingido | BT5: Meta | BU5: Atingido | BV5: Meta | BW5: Atingido | BX5: Meta | BY5: Atingido | BZ5: Meta | CA5: Atingido | CB5: Meta | CC5: Atingido | CD5: Meta | CE5: Atingido | CF5: Meta | CG5: Atingido | CH5: Meta | CI5: Atingido | CJ5: Meta | CK5: Atingido | CL5: Meta | CM5: Atingido | CN5: Meta | CO5: Atingido | CP5: Meta | CQ5: Atingido | CR5: Meta | CS5: Atingido | CT5: Meta | CU5: Atingido | CV5: Meta | CW5: Atingido | CX5: Meta | CY5: Atingido | CZ5: Meta | DA5: Atingido | DB5: Meta | DC5: Atingido | DD5: Meta | DE5: Atingido | DF5: Meta | DG5: Atingido | DH5: Meta | DI5: Atingido | DJ5: Meta | DK5: Atingido | DL5: Meta | DM5: Atingido | DN5: Meta | DO5: Atingido | DP5: Meta | DQ5: Atingido | DR5: Meta | DS5: Atingido | DT5: Meta | DU5: Atingido | DV5: Meta
B6: TOTAL | C6: Total de cadências abertas | D6: =SUM(F6+Q6+AA6+AK6+AU6+BE6+BO6+BY6+CI6+CS6+DC6+DM6) -> 0 | E6: =SUM(G6+R6+AB6+AL6+AV6+BF6+BP6+BZ6+CJ6+CT6+DD6+DN6) -> 248.01587 | F6: =SUM(F20+F34+F48+F62) -> 0 | G6: =SUM(G20+G34+G48+G62) -> 0 | H6: =F6/G6 -> #DIV/0! | I6: =SUM(I20+I34+I48+I62) -> 0 | J6: =SUM(J20+J34+J48+J62) -> 0 | K6: =SUM(K20+K34+K48+K62) -> 0 | L6: =SUM(L20+L34+L48+L62) -> 0 | M6: =SUM(M20+M34+M48+M62) -> 0 | N6: =SUM(N20+N34+N48+N62) -> 0 | O6: =SUM(O20+O34+O48+O62) -> 0 | P6: =SUM(P20+P34+P48+P62) -> 0 | ... DV6: =SUM(DV20+DV34+DV48+DV62) -> 0
C7: % Conversão em Lead Conectado | D7: =D8/D6 -> #DIV/0! | E7: =E8/E6 -> 0.15 | F7: =F8/F6 -> #DIV/0! | G7: =G8/G6 -> #DIV/0! | H7: - | I7: =I8/I6 -> #DIV/0! | J7: =J8/J6 -> #DIV/0! | K7: =K8/K6 -> #DIV/0! | L7: =L8/L6 -> #DIV/0! | M7: =M8/M6 -> #DIV/0! | N7: =N8/N6 -> #DIV/0! | O7: =O8/O6 -> #DIV/0! | P7: =P8/P6 -> #DIV/0! | ... DV7: =DV8/DV6 -> #DIV/0!
C8: Total de leads conectados | D8: =SUM(F8+Q8+AA8+AK8+AU8+BE8+BO8+BY8+CI8+CS8+DC8+DM8) -> 0 | E8: =SUM(G8+R8+AB8+AL8+AV8+BF8+BP8+BZ8+CJ8+CT8+DD8+DN8) -> 37.202381 | F8: =SUM(F22+F36+F50+F64) -> 0 | G8: =SUM(G22+G36+G50+G64) -> 0 | H8: =G8/F8 -> #DIV/0! | I8: =SUM(I22+I36+I50+I64) -> 0 | J8: =SUM(J22+J36+J50+J64) -> 0 | K8: =SUM(K22+K36+K50+K64) -> 0 | L8: =SUM(L22+L36+L50+L64) -> 0 | M8: =SUM(M22+M36+M50+M64) -> 0 | N8: =SUM(N22+N36+N50+N64) -> 0 | O8: =SUM(O22+O36+O50+O64) -> 0 | P8: =SUM(P22+P36+P50+P64) -> 0 | ... DV8: =SUM(DV22+DV36+DV50+DV64) -> 0
C9: % Conversão em Reunião agendada | D9: =D10/D8 -> #DIV/0! | E9: =E10/E8 -> 0.2 | F9: =F10/F8 -> #DIV/0! | G9: =G10/G8 -> #DIV/0! | H9: - | I9: =I10/I8 -> #DIV/0! | J9: =J10/J8 -> #DIV/0! | K9: =K10/K8 -> #DIV/0! | L9: =L10/L8 -> #DIV/0! | M9: =M10/M8 -> #DIV/0! | N9: =N10/N8 -> #DIV/0! | O9: =O10/O8 -> #DIV/0! | P9: =P10/P8 -> #DIV/0! | ... DV9: =DV10/DV8 -> #DIV/0!
C10: Total de reuniões agendadas | D10: =SUM(F10+Q10+AA10+AK10+AU10+BE10+BO10+BY10+CI10+CS10+DC10+DM10) -> 0 | E10: =SUM(G10+R10+AB10+AL10+AV10+BF10+BP10+BZ10+CJ10+CT10+DD10+DN10) -> 7.4404762 | F10: =SUM(F24+F38+F52+F66) -> 0 | G10: =SUM(G24+G38+G52+G66) -> 0 | H10: =G10/F10 -> #DIV/0! | I10: =SUM(I24+I38+I52+I66) -> 0 | J10: =SUM(J24+J38+J52+J66) -> 0 | K10: =SUM(K24+K38+K52+K66) -> 0 | L10: =SUM(L24+L38+L52+L66) -> 0 | M10: =SUM(M24+M38+M52+M66) -> 0 | N10: =SUM(N24+N38+N52+N66) -> 0 | O10: =SUM(O24+O38+O52+O66) -> 0 | P10: =SUM(P24+P38+P52+P66) -> 0 | ... DV10: =SUM(DV24+DV38+DV52+DV66) -> 0
C11: % de reunião realizada | D11: =D12/D10 -> #DIV/0! | E11: =E12/E10 -> 0.8 | F11: =F12/F10 -> #DIV/0! | G11: =G12/G10 -> #DIV/0! | H11: - | I11: =I12/I10 -> #DIV/0! | J11: =J12/J10 -> #DIV/0! | K11: =K12/K10 -> #DIV/0! | L11: =L12/L10 -> #DIV/0! | M11: =M12/M10 -> #DIV/0! | N11: =N12/N10 -> #DIV/0! | O11: =O12/O10 -> #DIV/0! | P11: =P12/P10 -> #DIV/0! | ... DV11: =DV12/DV10 -> #DIV/0!
C12: Total de reuniões realizadas | D12: =SUM(F12+Q12+AA12+AK12+AU12+BE12+BO12+BY12+CI12+CS12+DC12+DM12) -> 0 | E12: =SUM(G12+R12+AB12+AL12+AV12+BF12+BP12+BZ12+CJ12+CT12+DD12+DN12) -> 5.952381 | F12: =SUM(F26+F40+F54+F68) -> 0 | G12: =SUM(G26+G40+G54+G68) -> 0 | H12: =G12/F12 -> #DIV/0! | I12: =SUM(I26+I40+I54+I68) -> 0 | J12: =SUM(J26+J40+J54+J68) -> 0 | K12: =SUM(K26+K40+K54+K68) -> 0 | L12: =SUM(L26+L40+L54+L68) -> 0 | M12: =SUM(M26+M40+M54+M68) -> 0 | N12: =SUM(N26+N40+N54+N68) -> 0 | O12: =SUM(O26+O40+O54+O68) -> 0 | P12: =SUM(P26+P40+P54+P68) -> 0 | ... DV12: =SUM(DV26+DV40+DV54+DV68) -> 0
C13: % de propostas apresentadas | D13: =D14/D12 -> #DIV/0! | E13: =E14/E12 -> 0.7 | F13: =F14/F12 -> #DIV/0! | G13: =G14/G12 -> #DIV/0! | H13: - | I13: =I14/I12 -> #DIV/0! | J13: =J14/J12 -> #DIV/0! | K13: =K14/K12 -> #DIV/0! | L13: =L14/L12 -> #DIV/0! | M13: =M14/M12 -> #DIV/0! | N13: =N14/N12 -> #DIV/0! | O13: =O14/O12 -> #DIV/0! | P13: =P14/P12 -> #DIV/0! | ... DV13: =DV14/DV12 -> #DIV/0!
C14: Total de propostas apresentadas | D14: =SUM(F14+Q14+AA14+AK14+AU14+BE14+BO14+BY14+CI14+CS14+DC14+DM14) -> 0 | E14: =SUM(G14+R14+AB14+AL14+AV14+BF14+BP14+BZ14+CJ14+CT14+DD14+DN14) -> 4.1666667 | F14: =SUM(F28+F42+F56+F70) -> 0 | G14: =SUM(G28+G42+G56+G70) -> 0 | H14: =G14/F14 -> #DIV/0! | I14: =SUM(I28+I42+I56+I70) -> 0 | J14: =SUM(J28+J42+J56+J70) -> 0 | K14: =SUM(K28+K42+K56+K70) -> 0 | L14: =SUM(L28+L42+L56+L70) -> 0 | M14: =SUM(M28+M42+M56+M70) -> 0 | N14: =SUM(N28+N42+N56+N70) -> 0 | O14: =SUM(O28+O42+O56+O70) -> 0 | P14: =SUM(P28+P42+P56+P70) -> 0 | ... DV14: =SUM(DV28+DV42+DV56+DV70) -> 0
C15: % de fechamento | D15: =D16/D14 -> #DIV/0! | E15: =E16/E14 -> 0.4 | F15: =F16/F14 -> #DIV/0! | G15: =G16/G14 -> #DIV/0! | H15: - | I15: =I16/I14 -> #DIV/0! | J15: =J16/J14 -> #DIV/0! | K15: =K16/K14 -> #DIV/0! | L15: =L16/L14 -> #DIV/0! | M15: =M16/M14 -> #DIV/0! | N15: =N16/N14 -> #DIV/0! | O15: =O16/O14 -> #DIV/0! | P15: =P16/P14 -> #DIV/0! | ... DV15: =DV16/DV14 -> #DIV/0!
C16: Total de propostas fechadas | D16: =SUM(F16+Q16+AA16+AK16+AU16+BE16+BO16+BY16+CI16+CS16+DC16+DM16) -> 0 | E16: =SUM(G16+R16+AB16+AL16+AV16+BF16+BP16+BZ16+CJ16+CT16+DD16+DN16) -> 1.6666667 | F16: =SUM(F30+F44+F58+F72) -> 0 | G16: =SUM(G30+G44+G58+G72) -> 0 | H16: =G16/F16 -> #DIV/0! | I16: =SUM(I30+I44+I58+I72) -> 0 | J16: =SUM(J30+J44+J58+J72) -> 0 | K16: =SUM(K30+K44+K58+K72) -> 0 | L16: =SUM(L30+L44+L58+L72) -> 0 | M16: =SUM(M30+M44+M58+M72) -> 0 | N16: =SUM(N30+N44+N58+N72) -> 0 | O16: =SUM(O30+O44+O58+O72) -> 0 | P16: =SUM(P30+P44+P58+P72) -> 0 | ... DV16: =SUM(DV30+DV44+DV58+DV72) -> 0
C17: Total de faturamento | D17: =SUM(F17+Q17+AA17+AK17+AU17+BE17+BO17+BY17+CI17+CS17+DC17+DM17) -> 0 | E17: =SUM(G17+R17+AB17+AL17+AV17+BF17+BP17+BZ17+CJ17+CT17+DD17+DN17) -> 4166.6667 | F17: =SUM(F31+F45+F59+F73) -> 0 | G17: =SUM(G31+G45+G59+G73) -> 0 | H17: =G17/F17 -> #DIV/0! | I17: =SUM(I31+I45+I59+I73) -> 0 | J17: =SUM(J31+J45+J59+J73) -> 0 | K17: =SUM(K31+K45+K59+K73) -> 0 | L17: =SUM(L31+L45+L59+L73) -> 0 | M17: =SUM(M31+M45+M59+M73) -> 0 | N17: =SUM(N31+N45+N59+N73) -> 0 | O17: =SUM(O31+O45+O59+O73) -> 0 | P17: =SUM(P31+P45+P59+P73) -> 0 | ... DV17: =SUM(DV31+DV45+DV59+DV73) -> 0
C18: Ticket médio | D18: =D17/D16 -> #DIV/0! | E18: =E17/E16 -> 2500 | F18: =F17/F16 -> #DIV/0! | G18: =SUM(G32+G46+G60+G74) -> 10000 | H18: =G18/F18 -> #DIV/0! | I18: =SUM(I32+I46+I60+I74) -> #DIV/0! | J18: =SUM(J32+J46+J60+J74) -> 10000 | K18: =SUM(K32+K46+K60+K74) -> #DIV/0! | L18: =SUM(L32+L46+L60+L74) -> 10000 | M18: =SUM(M32+M46+M60+M74) -> #DIV/0! | N18: =SUM(N32+N46+N60+N74) -> 10000 | O18: =SUM(O32+O46+O60+O74) -> #DIV/0! | P18: =SUM(P32+P46+P60+P74) -> 10000 | Q18: =Q17/Q16 -> #DIV/0! | R18: =SUM(R32+R46+R60+R74) -> 10000 | S18: =SUM(S32+S46+S60+S74) -> #DIV/0! | T18: =SUM(T32+T46+T60+T74) -> 10000 | U18: =SUM(U32+U46+U60+U74) -> #DIV/0! | V18: =SUM(V32+V46+V60+V74) -> 10000 | W18: =SUM(W32+W46+W60+W74) -> #DIV/0! | X18: =SUM(X32+X46+X60+X74) -> 10000 | Y18: =SUM(Y32+Y46+Y60+Y74) -> #DIV/0! | Z18: =SUM(Z32+Z46+Z60+Z74) -> 10000 | AA18: =AA17/AA16 -> #DIV/0! | AB18: =SUM(AB32+AB46+AB60+AB74) -> 10000 | AC18: =SUM(AC32+AC46+AC60+AC74) -> #DIV/0! | AD18: =SUM(AD32+AD46+AD60+AD74) -> 10000 | AE18: =SUM(AE32+AE46+AE60+AE74) -> #DIV/0! | AF18: =SUM(AF32+AF46+AF60+AF74) -> 10000 | AG18: =SUM(AG32+AG46+AG60+AG74) -> #DIV/0! | AH18: =SUM(AH32+AH46+AH60+AH74) -> 10000 | AI18: =SUM(AI32+AI46+AI60+AI74) -> #DIV/0! | AJ18: =SUM(AJ32+AJ46+AJ60+AJ74) -> 10000 | AK18: =AK17/AK16 -> #DIV/0! | AL18: =SUM(AL32+AL46+AL60+AL74) -> 10000 | AM18: =SUM(AM32+AM46+AM60+AM74) -> #DIV/0! | AN18: =SUM(AN32+AN46+AN60+AN74) -> 10000 | AO18: =SUM(AO32+AO46+AO60+AO74) -> #DIV/0! | AP18: =SUM(AP32+AP46+AP60+AP74) -> 10000 | AQ18: =SUM(AQ32+AQ46+AQ60+AQ74) -> #DIV/0! | AR18: =SUM(AR32+AR46+AR60+AR74) -> 10000 | AS18: =SUM(AS32+AS46+AS60+AS74) -> #DIV/0! | AT18: =SUM(AT32+AT46+AT60+AT74) -> 10000 | AU18: =AU17/AU16 -> #DIV/0! | AV18: =SUM(AV32+AV46+AV60+AV74) -> 10000 | AW18: =SUM(AW32+AW46+AW60+AW74) -> #DIV/0! | AX18: =SUM(AX32+AX46+AX60+AX74) -> 10000 | AY18: =SUM(AY32+AY46+AY60+AY74) -> #DIV/0! | AZ18: =SUM(AZ32+AZ46+AZ60+AZ74) -> 10000 | BA18: =SUM(BA32+BA46+BA60+BA74) -> #DIV/0! | BB18: =SUM(BB32+BB46+BB60+BB74) -> 10000 | BC18: =SUM(BC32+BC46+BC60+BC74) -> #DIV/0! | BD18: =SUM(BD32+BD46+BD60+BD74) -> 10000 | BE18: =BE17/BE16 -> #DIV/0! | BF18: ='Dados da Operação'!$C$5 -> 2500 | BG18: =SUM(BG32+BG46+BG60+BG74) -> #DIV/0! | BH18: ='Dados da Operação'!$C$5 -> 2500 | BI18: =SUM(BI32+BI46+BI60+BI74) -> #DIV/0! | BJ18: ='Dados da Operação'!$C$5 -> 2500 | BK18: =SUM(BK32+BK46+BK60+BK74) -> #DIV/0! | BL18: ='Dados da Operação'!$C$5 -> 2500 | BM18: =SUM(BM32+BM46+BM60+BM74) -> #DIV/0! | BN18: ='Dados da Operação'!$C$5 -> 2500 | BO18: =BO17/BO16 -> #DIV/0! | BP18: ='Dados da Operação'!$C$5 -> 2500 | BQ18: =SUM(BQ32+BQ46+BQ60+BQ74) -> #DIV/0! | BR18: =SUM(BR32+BR46+BR60+BR74) -> 10000 | BS18: =SUM(BS32+BS46+BS60+BS74) -> #DIV/0! | BT18: =SUM(BT32+BT46+BT60+BT74) -> 10000 | BU18: =SUM(BU32+BU46+BU60+BU74) -> #DIV/0! | BV18: =SUM(BV32+BV46+BV60+BV74) -> 10000 | BW18: =SUM(BW32+BW46+BW60+BW74) -> #DIV/0! | BX18: =SUM(BX32+BX46+BX60+BX74) -> 10000 | BY18: =BY17/BY16 -> #DIV/0! | BZ18: ='Dados da Operação'!$C$5 -> 2500 | CA18: =SUM(CA32+CA46+CA60+CA74) -> #DIV/0! | CB18: =SUM(CB32+CB46+CB60+CB74) -> 10000 | CC18: =SUM(CC32+CC46+CC60+CC74) -> #DIV/0! | CD18: =SUM(CD32+CD46+CD60+CD74) -> 10000 | CE18: =SUM(CE32+CE46+CE60+CE74) -> #DIV/0! | CF18: =SUM(CF32+CF46+CF60+CF74) -> 10000 | CG18: =SUM(CG32+CG46+CG60+CG74) -> #DIV/0! | CH18: =SUM(CH32+CH46+CH60+CH74) -> 10000 | CI18: =CI17/CI16 -> #DIV/0! | CJ18: ='Dados da Operação'!$C$5 -> 2500 | CK18: =SUM(CK32+CK46+CK60+CK74) -> #DIV/0! | CL18: =SUM(CL32+CL46+CL60+CL74) -> 10000 | CM18: =SUM(CM32+CM46+CM60+CM74) -> #DIV/0! | CN18: =SUM(CN32+CN46+CN60+CN74) -> 10000 | CO18: =SUM(CO32+CO46+CO60+CO74) -> #DIV/0! | CP18: =SUM(CP32+CP46+CP60+CP74) -> 10000 | CQ18: =SUM(CQ32+CQ46+CQ60+CQ74) -> #DIV/0! | CR18: =SUM(CR32+CR46+CR60+CR74) -> 10000 | CS18: =CS17/CS16 -> #DIV/0! | CT18: ='Dados da Operação'!$C$5 -> 2500 | CU18: =SUM(CU32+CU46+CU60+CU74) -> #DIV/0! | CV18: =SUM(CV32+CV46+CV60+CV74) -> 10000 | CW18: =SUM(CW32+CW46+CW60+CW74) -> #DIV/0! | CX18: =SUM(CX32+CX46+CX60+CX74) -> 10000 | CY18: =SUM(CY32+CY46+CY60+CY74) -> #DIV/0! | CZ18: =SUM(CZ32+CZ46+CZ60+CZ74) -> 10000 | DA18: =SUM(DA32+DA46+DA60+DA74) -> #DIV/0! | DB18: =SUM(DB32+DB46+DB60+DB74) -> 10000 | DC18: =DC17/DC16 -> #DIV/0! | DD18: ='Dados da Operação'!$C$5 -> 2500 | DE18: =SUM(DE32+DE46+DE60+DE74) -> #DIV/0! | DF18: =SUM(DF32+DF46+DF60+DF74) -> 10000 | DG18: =SUM(DG32+DG46+DG60+DG74) -> #DIV/0! | DH18: =SUM(DH32+DH46+DH60+DH74) -> 10000 | DI18: =SUM(DI32+DI46+DI60+DI74) -> #DIV/0! | DJ18: =SUM(DJ32+DJ46+DJ60+DJ74) -> 10000 | DK18: =SUM(DK32+DK46+DK60+DK74) -> #DIV/0! | DL18: =SUM(DL32+DL46+DL60+DL74) -> 10000 | DM18: =DM17/DM16 -> #DIV/0! | DN18: ='Dados da Operação'!$C$5 -> 2500 | DO18: =SUM(DO32+DO46+DO60+DO74) -> #DIV/0! | DP18: =SUM(DP32+DP46+DP60+DP74) -> 10000 | DQ18: =SUM(DQ32+DQ46+DQ60+DQ74) -> #DIV/0! | DR18: =SUM(DR32+DR46+DR60+DR74) -> 10000 | DS18: =SUM(DS32+DS46+DS60+DS74) -> #DIV/0! | DT18: =SUM(DT32+DT46+DT60+DT74) -> 10000 | DU18: =SUM(DU32+DU46+DU60+DU74) -> #DIV/0! | DV18: =SUM(DV32+DV46+DV60+DV74) -> 10000
B20: OUTBOUND | C20: Total de cadências abertas | D20: =SUM(F20+Q20+AA20+AK20+AU20+BE20+BO20+BY20+CI20+CS20+DC20+DM20) -> 0 | E20: =SUM(G20+R20+AB20+AL20+AV20+BF20+BP20+BZ20+CJ20+CT20+DD20+DN20) -> 248.01587 | F20: =SUM(I20+K20+M20+O20) -> 0 | G20: =G22/G21 -> 0 | H20: =F20/G20 -> #DIV/0! | J20: =G20/4 -> 0 | L20: =G20/4 -> 0 | N20: =G20/4 -> 0 | P20: =G20/4 -> 0 | Q20: =SUM(S20+U20+W20+Y20) -> 0 | T20: =R20/4 -> 0 | V20: =R20/4 -> 0 | X20: =R20/4 -> 0 | Z20: =R20/4 -> 0 | AA20: =SUM(AC20+AE20+AG20+AI20) -> 0 | AD20: =AB20/4 -> 0 | AF20: =AB20/4 -> 0 | AH20: =AB20/4 -> 0 | AJ20: =AB20/4 -> 0 | AK20: =SUM(AM20+AO20+AQ20+AS20) -> 0 | AN20: =AL20/4 -> 0 | AP20: =AL20/4 -> 0 | AR20: =AL20/4 -> 0 | AT20: =AL20/4 -> 0 | AU20: =SUM(AW20+AY20+BA20+BC20) -> 0 | AX20: =AV20/4 -> 0 | AZ20: =AV20/4 -> 0 | BB20: =AV20/4 -> 0 | BD20: =AV20/4 -> 0 | BE20: =SUM(BG20+BI20+BK20+BM20) -> 0 | BF20: =BF22/BF21 -> 248.01587 | BH20: =BF20/4 -> 62.003968 | BJ20: =BF20/4 -> 62.003968 | BL20: =BF20/4 -> 62.003968 | BN20: =BF20/4 -> 62.003968 | BO20: =SUM(BQ20+BS20+BU20+BW20) -> 0 | BR20: =BP20/4 -> 0 | BT20: =BP20/4 -> 0 | BV20: =BP20/4 -> 0 | BX20: =BP20/4 -> 0 | BY20: =SUM(CA20+CC20+CE20+CG20) -> 0 | CB20: =BZ20/4 -> 0 | CD20: =BZ20/4 -> 0 | CF20: =BZ20/4 -> 0 | CH20: =BZ20/4 -> 0 | CI20: =SUM(CK20+CM20+CO20+CQ20) -> 0 | CL20: =CJ20/4 -> 0 | CN20: =CJ20/4 -> 0 | CP20: =CJ20/4 -> 0 | CR20: =CJ20/4 -> 0 | CS20: =SUM(CU20+CW20+CY20+DA20) -> 0 | CV20: =CT20/4 -> 0 | CX20: =CT20/4 -> 0 | CZ20: =CT20/4 -> 0 | DB20: =CT20/4 -> 0 | DC20: =SUM(DE20+DG20+DI20+DK20) -> 0 | DF20: =DD20/4 -> 0 | DH20: =DD20/4 -> 0 | DJ20: =DD20/4 -> 0 | DL20: =DD20/4 -> 0 | DM20: =SUM(DO20+DQ20+DS20+DU20) -> 0 | DP20: =DN20/4 -> 0 | DR20: =DN20/4 -> 0 | DT20: =DN20/4 -> 0 | DV20: =DN20/4 -> 0
C21: % Conversão em Lead Conectado | D21: =D22/D20 -> #DIV/0! | E21: =E22/E20 -> 0.15 | F21: =F22/F20 -> #DIV/0! | G21: 0.3 | H21: - | I21: =I22/I20 -> #DIV/0! | J21: =G21 -> 0.3 | K21: =K22/K20 -> #DIV/0! | L21: =G21 -> 0.3 | M21: =M22/M20 -> #DIV/0! | N21: =G21 -> 0.3 | O21: =O22/O20 -> #DIV/0! | P21: =G21 -> 0.3 | Q21: =Q22/Q20 -> #DIV/0! | S21: =S22/S20 -> #DIV/0! | T21: =R21 | U21: =U22/U20 -> #DIV/0! | V21: =R21 | W21: =W22/W20 -> #DIV/0! | X21: =R21 | Y21: =Y22/Y20 -> #DIV/0! | Z21: =R21 | AA21: =AA22/AA20 -> #DIV/0! | AC21: =AC22/AC20 -> #DIV/0! | AD21: =AB21 | AE21: =AE22/AE20 -> #DIV/0! | AF21: =AB21 | AG21: =AG22/AG20 -> #DIV/0! | AH21: =AB21 | AI21: =AI22/AI20 -> #DIV/0! | AJ21: =AB21 | AK21: =AK22/AK20 -> #DIV/0! | AM21: =AM22/AM20 -> #DIV/0! | AN21: =AL21 | AO21: =AO22/AO20 -> #DIV/0! | AP21: =AL21 | AQ21: =AQ22/AQ20 -> #DIV/0! | AR21: =AL21 | AS21: =AS22/AS20 -> #DIV/0! | AT21: =AL21 | AU21: =AU22/AU20 -> #DIV/0! | AW21: =AW22/AW20 -> #DIV/0! | AX21: =AV21 | AY21: =AY22/AY20 -> #DIV/0! | AZ21: =AV21 | BA21: =BA22/BA20 -> #DIV/0! | BB21: =AV21 | BC21: =BC22/BC20 -> #DIV/0! | BD21: =AV21 | BE21: =BE22/BE20 -> #DIV/0! | BF21: 0.15 | BG21: =BG22/BG20 -> #DIV/0! | BH21: =BF21 -> 0.15 | BI21: =BI22/BI20 -> #DIV/0! | BJ21: =BF21 -> 0.15 | BK21: =BK22/BK20 -> #DIV/0! | BL21: =BF21 -> 0.15 | BM21: =BM22/BM20 -> #DIV/0! | BN21: =BF21 -> 0.15 | BO21: =BO22/BO20 -> #DIV/0! | BQ21: =BQ22/BQ20 -> #DIV/0! | BR21: =BP21 | BS21: =BS22/BS20 -> #DIV/0! | BT21: =BP21 | BU21: =BU22/BU20 -> #DIV/0! | BV21: =BP21 | BW21: =BW22/BW20 -> #DIV/0! | BX21: =BP21 | BY21: =BY22/BY20 -> #DIV/0! | CA21: =CA22/CA20 -> #DIV/0! | CB21: =BZ21 | CC21: =CC22/CC20 -> #DIV/0! | CD21: =BZ21 | CE21: =CE22/CE20 -> #DIV/0! | CF21: =BZ21 | CG21: =CG22/CG20 -> #DIV/0! | CH21: =BZ21 | CI21: =CI22/CI20 -> #DIV/0! | CK21: =CK22/CK20 -> #DIV/0! | CL21: =CJ21 | CM21: =CM22/CM20 -> #DIV/0! | CN21: =CJ21 | CO21: =CO22/CO20 -> #DIV/0! | CP21: =CJ21 | CQ21: =CQ22/CQ20 -> #DIV/0! | CR21: =CJ21 | CS21: =CS22/CS20 -> #DIV/0! | CU21: =CU22/CU20 -> #DIV/0! | CV21: =CT21 | CW21: =CW22/CW20 -> #DIV/0! | CX21: =CT21 | CY21: =CY22/CY20 -> #DIV/0! | CZ21: =CT21 | DA21: =DA22/DA20 -> #DIV/0! | DB21: =CT21 | DC21: =DC22/DC20 -> #DIV/0! | DE21: =DE22/DE20 -> #DIV/0! | DF21: =DD21 | DG21: =DG22/DG20 -> #DIV/0! | DH21: =DD21 | DI21: =DI22/DI20 -> #DIV/0! | DJ21: =DD21 | DK21: =DK22/DK20 -> #DIV/0! | DL21: =DD21 | DM21: =DM22/DM20 -> #DIV/0! | DO21: =DO22/DO20 -> #DIV/0! | DP21: =DN21 | DQ21: =DQ22/DQ20 -> #DIV/0! | DR21: =DN21 | DS21: =DS22/DS20 -> #DIV/0! | DT21: =DN21 | DU21: =DU22/DU20 -> #DIV/0! | DV21: =DN21
C22: Total de leads conectados | D22: =SUM(F22+Q22+AA22+AK22+AU22+BE22+BO22+BY22+CI22+CS22+DC22+DM22) -> 0 | E22: =SUM(G22+R22+AB22+AL22+AV22+BF22+BP22+BZ22+CJ22+CT22+DD22+DN22) -> 37.202381 | F22: =SUM(I22+K22+M22+O22) -> 0 | G22: =G24/G23 -> 0 | H22: =G22/F22 -> #DIV/0! | J22: =G22/4 -> 0 | L22: =G22/4 -> 0 | N22: =G22/4 -> 0 | P22: =G22/4 -> 0 | Q22: =SUM(S22+U22+W22+Y22) -> 0 | T22: =R22/4 -> 0 | V22: =R22/4 -> 0 | X22: =R22/4 -> 0 | Z22: =R22/4 -> 0 | AA22: =SUM(AC22+AE22+AG22+AI22) -> 0 | AD22: =AB22/4 -> 0 | AF22: =AB22/4 -> 0 | AH22: =AB22/4 -> 0 | AJ22: =AB22/4 -> 0 | AK22: =SUM(AM22+AO22+AQ22+AS22) -> 0 | AN22: =AL22/4 -> 0 | AP22: =AL22/4 -> 0 | AR22: =AL22/4 -> 0 | AT22: =AL22/4 -> 0 | AU22: =SUM(AW22+AY22+BA22+BC22) -> 0 | AX22: =AV22/4 -> 0 | AZ22: =AV22/4 -> 0 | BB22: =AV22/4 -> 0 | BD22: =AV22/4 -> 0 | BE22: =SUM(BG22+BI22+BK22+BM22) -> 0 | BF22: =BF24/BF23 -> 37.202381 | BH22: =BF22/4 -> 9.3005952 | BJ22: =BF22/4 -> 9.3005952 | BL22: =BF22/4 -> 9.3005952 | BN22: =BF22/4 -> 9.3005952 | BO22: =SUM(BQ22+BS22+BU22+BW22) -> 0 | BR22: =BP22/4 -> 0 | BT22: =BP22/4 -> 0 | BV22: =BP22/4 -> 0 | BX22: =BP22/4 -> 0 | BY22: =SUM(CA22+CC22+CE22+CG22) -> 0 | CB22: =BZ22/4 -> 0 | CD22: =BZ22/4 -> 0 | CF22: =BZ22/4 -> 0 | CH22: =BZ22/4 -> 0 | CI22: =SUM(CK22+CM22+CO22+CQ22) -> 0 | CL22: =CJ22/4 -> 0 | CN22: =CJ22/4 -> 0 | CP22: =CJ22/4 -> 0 | CR22: =CJ22/4 -> 0 | CS22: =SUM(CU22+CW22+CY22+DA22) -> 0 | CV22: =CT22/4 -> 0 | CX22: =CT22/4 -> 0 | CZ22: =CT22/4 -> 0 | DB22: =CT22/4 -> 0 | DC22: =SUM(DE22+DG22+DI22+DK22) -> 0 | DF22: =DD22/4 -> 0 | DH22: =DD22/4 -> 0 | DJ22: =DD22/4 -> 0 | DL22: =DD22/4 -> 0 | DM22: =SUM(DO22+DQ22+DS22+DU22) -> 0 | DP22: =DN22/4 -> 0 | DR22: =DN22/4 -> 0 | DT22: =DN22/4 -> 0 | DV22: =DN22/4 -> 0
C23: % Conversão em Reunião agendada | D23: =D24/D22 -> #DIV/0! | E23: =E24/E22 -> 0.2 | F23: =F24/F22 -> #DIV/0! | G23: 0.3 | H23: - | I23: =I24/I22 -> #DIV/0! | J23: =G23 -> 0.3 | K23: =K24/K22 -> #DIV/0! | L23: =G23 -> 0.3 | M23: =M24/M22 -> #DIV/0! | N23: =G23 -> 0.3 | O23: =O24/O22 -> #DIV/0! | P23: =G23 -> 0.3 | Q23: =Q24/Q22 -> #DIV/0! | S23: =S24/S22 -> #DIV/0! | T23: =R23 | U23: =U24/U22 -> #DIV/0! | V23: =R23 | W23: =W24/W22 -> #DIV/0! | X23: =R23 | Y23: =Y24/Y22 -> #DIV/0! | Z23: =R23 | AA23: =AA24/AA22 -> #DIV/0! | AC23: =AC24/AC22 -> #DIV/0! | AD23: =AB23 | AE23: =AE24/AE22 -> #DIV/0! | AF23: =AB23 | AG23: =AG24/AG22 -> #DIV/0! | AH23: =AB23 | AI23: =AI24/AI22 -> #DIV/0! | AJ23: =AB23 | AK23: =AK24/AK22 -> #DIV/0! | AM23: =AM24/AM22 -> #DIV/0! | AN23: =AL23 | AO23: =AO24/AO22 -> #DIV/0! | AP23: =AL23 | AQ23: =AQ24/AQ22 -> #DIV/0! | AR23: =AL23 | AS23: =AS24/AS22 -> #DIV/0! | AT23: =AL23 | AU23: =AU24/AU22 -> #DIV/0! | AW23: =AW24/AW22 -> #DIV/0! | AX23: =AV23 | AY23: =AY24/AY22 -> #DIV/0! | AZ23: =AV23 | BA23: =BA24/BA22 -> #DIV/0! | BB23: =AV23 | BC23: =BC24/BC22 -> #DIV/0! | BD23: =AV23 | BE23: =BE24/BE22 -> #DIV/0! | BF23: 0.2 | BG23: =BG24/BG22 -> #DIV/0! | BH23: =BF23 -> 0.2 | BI23: =BI24/BI22 -> #DIV/0! | BJ23: =BF23 -> 0.2 | BK23: =BK24/BK22 -> #DIV/0! | BL23: =BF23 -> 0.2 | BM23: =BM24/BM22 -> #DIV/0! | BN23: =BF23 -> 0.2 | BO23: =BO24/BO22 -> #DIV/0! | BQ23: =BQ24/BQ22 -> #DIV/0! | BR23: =BP23 | BS23: =BS24/BS22 -> #DIV/0! | BT23: =BP23 | BU23: =BU24/BU22 -> #DIV/0! | BV23: =BP23 | BW23: =BW24/BW22 -> #DIV/0! | BX23: =BP23 | BY23: =BY24/BY22 -> #DIV/0! | CA23: =CA24/CA22 -> #DIV/0! | CB23: =BZ23 | CC23: =CC24/CC22 -> #DIV/0! | CD23: =BZ23 | CE23: =CE24/CE22 -> #DIV/0! | CF23: =BZ23 | CG23: =CG24/CG22 -> #DIV/0! | CH23: =BZ23 | CI23: =CI24/CI22 -> #DIV/0! | CK23: =CK24/CK22 -> #DIV/0! | CL23: =CJ23 | CM23: =CM24/CM22 -> #DIV/0! | CN23: =CJ23 | CO23: =CO24/CO22 -> #DIV/0! | CP23: =CJ23 | CQ23: =CQ24/CQ22 -> #DIV/0! | CR23: =CJ23 | CS23: =CS24/CS22 -> #DIV/0! | CU23: =CU24/CU22 -> #DIV/0! | CV23: =CT23 | CW23: =CW24/CW22 -> #DIV/0! | CX23: =CT23 | CY23: =CY24/CY22 -> #DIV/0! | CZ23: =CT23 | DA23: =DA24/DA22 -> #DIV/0! | DB23: =CT23 | DC23: =DC24/DC22 -> #DIV/0! | DE23: =DE24/DE22 -> #DIV/0! | DF23: =DD23 | DG23: =DG24/DG22 -> #DIV/0! | DH23: =DD23 | DI23: =DI24/DI22 -> #DIV/0! | DJ23: =DD23 | DK23: =DK24/DK22 -> #DIV/0! | DL23: =DD23 | DM23: =DM24/DM22 -> #DIV/0! | DO23: =DO24/DO22 -> #DIV/0! | DP23: =DN23 | DQ23: =DQ24/DQ22 -> #DIV/0! | DR23: =DN23 | DS23: =DS24/DS22 -> #DIV/0! | DT23: =DN23 | DU23: =DU24/DU22 -> #DIV/0! | DV23: =DN23
C24: Total de reuniões agendadas | D24: =SUM(F24+Q24+AA24+AK24+AU24+BE24+BO24+BY24+CI24+CS24+DC24+DM24) -> 0 | E24: =SUM(G24+R24+AB24+AL24+AV24+BF24+BP24+BZ24+CJ24+CT24+DD24+DN24) -> 7.4404762 | F24: =SUM(I24+K24+M24+O24) -> 0 | G24: =G26/G25 -> 0 | H24: =G24/F24 -> #DIV/0! | J24: =G24/4 -> 0 | L24: =G24/4 -> 0 | N24: =G24/4 -> 0 | P24: =G24/4 -> 0 | Q24: =SUM(S24+U24+W24+Y24) -> 0 | T24: =R24/4 -> 0 | V24: =R24/4 -> 0 | X24: =R24/4 -> 0 | Z24: =R24/4 -> 0 | AA24: =SUM(AC24+AE24+AG24+AI24) -> 0 | AD24: =AB24/4 -> 0 | AF24: =AB24/4 -> 0 | AH24: =AB24/4 -> 0 | AJ24: =AB24/4 -> 0 | AK24: =SUM(AM24+AO24+AQ24+AS24) -> 0 | AN24: =AL24/4 -> 0 | AP24: =AL24/4 -> 0 | AR24: =AL24/4 -> 0 | AT24: =AL24/4 -> 0 | AU24: =SUM(AW24+AY24+BA24+BC24) -> 0 | AX24: =AV24/4 -> 0 | AZ24: =AV24/4 -> 0 | BB24: =AV24/4 -> 0 | BD24: =AV24/4 -> 0 | BE24: =SUM(BG24+BI24+BK24+BM24) -> 0 | BF24: =BF26/BF25 -> 7.4404762 | BH24: =BF24/4 -> 1.860119 | BJ24: =BF24/4 -> 1.860119 | BL24: =BF24/4 -> 1.860119 | BN24: =BF24/4 -> 1.860119 | BO24: =SUM(BQ24+BS24+BU24+BW24) -> 0 | BR24: =BP24/4 -> 0 | BT24: =BP24/4 -> 0 | BV24: =BP24/4 -> 0 | BX24: =BP24/4 -> 0 | BY24: =SUM(CA24+CC24+CE24+CG24) -> 0 | CB24: =BZ24/4 -> 0 | CD24: =BZ24/4 -> 0 | CF24: =BZ24/4 -> 0 | CH24: =BZ24/4 -> 0 | CI24: =SUM(CK24+CM24+CO24+CQ24) -> 0 | CL24: =CJ24/4 -> 0 | CN24: =CJ24/4 -> 0 | CP24: =CJ24/4 -> 0 | CR24: =CJ24/4 -> 0 | CS24: =SUM(CU24+CW24+CY24+DA24) -> 0 | CV24: =CT24/4 -> 0 | CX24: =CT24/4 -> 0 | CZ24: =CT24/4 -> 0 | DB24: =CT24/4 -> 0 | DC24: =SUM(DE24+DG24+DI24+DK24) -> 0 | DF24: =DD24/4 -> 0 | DH24: =DD24/4 -> 0 | DJ24: =DD24/4 -> 0 | DL24: =DD24/4 -> 0 | DM24: =SUM(DO24+DQ24+DS24+DU24) -> 0 | DP24: =DN24/4 -> 0 | DR24: =DN24/4 -> 0 | DT24: =DN24/4 -> 0 | DV24: =DN24/4 -> 0
C25: % de reunião realizada | D25: =D26/D24 -> #DIV/0! | E25: =E26/E24 -> 0.8 | F25: =F26/F24 -> #DIV/0! | G25: 0.9 | H25: - | I25: =I26/I24 -> #DIV/0! | J25: =G25 -> 0.9 | K25: =K26/K24 -> #DIV/0! | L25: =G25 -> 0.9 | M25: =M26/M24 -> #DIV/0! | N25: =G25 -> 0.9 | O25: =O26/O24 -> #DIV/0! | P25: =G25 -> 0.9 | Q25: =Q26/Q24 -> #DIV/0! | S25: =S26/S24 -> #DIV/0! | T25: =R25 | U25: =U26/U24 -> #DIV/0! | V25: =R25 | W25: =W26/W24 -> #DIV/0! | X25: =R25 | Y25: =Y26/Y24 -> #DIV/0! | Z25: =R25 | AA25: =AA26/AA24 -> #DIV/0! | AC25: =AC26/AC24 -> #DIV/0! | AD25: =AB25 | AE25: =AE26/AE24 -> #DIV/0! | AF25: =AB25 | AG25: =AG26/AG24 -> #DIV/0! | AH25: =AB25 | AI25: =AI26/AI24 -> #DIV/0! | AJ25: =AB25 | AK25: =AK26/AK24 -> #DIV/0! | AM25: =AM26/AM24 -> #DIV/0! | AN25: =AL25 | AO25: =AO26/AO24 -> #DIV/0! | AP25: =AL25 | AQ25: =AQ26/AQ24 -> #DIV/0! | AR25: =AL25 | AS25: =AS26/AS24 -> #DIV/0! | AT25: =AL25 | AU25: =AU26/AU24 -> #DIV/0! | AW25: =AW26/AW24 -> #DIV/0! | AX25: =AV25 | AY25: =AY26/AY24 -> #DIV/0! | AZ25: =AV25 | BA25: =BA26/BA24 -> #DIV/0! | BB25: =AV25 | BC25: =BC26/BC24 -> #DIV/0! | BD25: =AV25 | BE25: =BE26/BE24 -> #DIV/0! | BF25: 0.8 | BG25: =BG26/BG24 -> #DIV/0! | BH25: =BF25 -> 0.8 | BI25: =BI26/BI24 -> #DIV/0! | BJ25: =BF25 -> 0.8 | BK25: =BK26/BK24 -> #DIV/0! | BL25: =BF25 -> 0.8 | BM25: =BM26/BM24 -> #DIV/0! | BN25: =BF25 -> 0.8 | BO25: =BO26/BO24 -> #DIV/0! | BQ25: =BQ26/BQ24 -> #DIV/0! | BR25: =BP25 | BS25: =BS26/BS24 -> #DIV/0! | BT25: =BP25 | BU25: =BU26/BU24 -> #DIV/0! | BV25: =BP25 | BW25: =BW26/BW24 -> #DIV/0! | BX25: =BP25 | BY25: =BY26/BY24 -> #DIV/0! | CA25: =CA26/CA24 -> #DIV/0! | CB25: =BZ25 | CC25: =CC26/CC24 -> #DIV/0! | CD25: =BZ25 | CE25: =CE26/CE24 -> #DIV/0! | CF25: =BZ25 | CG25: =CG26/CG24 -> #DIV/0! | CH25: =BZ25 | CI25: =CI26/CI24 -> #DIV/0! | CK25: =CK26/CK24 -> #DIV/0! | CL25: =CJ25 | CM25: =CM26/CM24 -> #DIV/0! | CN25: =CJ25 | CO25: =CO26/CO24 -> #DIV/0! | CP25: =CJ25 | CQ25: =CQ26/CQ24 -> #DIV/0! | CR25: =CJ25 | CS25: =CS26/CS24 -> #DIV/0! | CU25: =CU26/CU24 -> #DIV/0! | CV25: =CT25 | CW25: =CW26/CW24 -> #DIV/0! | CX25: =CT25 | CY25: =CY26/CY24 -> #DIV/0! | CZ25: =CT25 | DA25: =DA26/DA24 -> #DIV/0! | DB25: =CT25 | DC25: =DC26/DC24 -> #DIV/0! | DE25: =DE26/DE24 -> #DIV/0! | DF25: =DD25 | DG25: =DG26/DG24 -> #DIV/0! | DH25: =DD25 | DI25: =DI26/DI24 -> #DIV/0! | DJ25: =DD25 | DK25: =DK26/DK24 -> #DIV/0! | DL25: =DD25 | DM25: =DM26/DM24 -> #DIV/0! | DO25: =DO26/DO24 -> #DIV/0! | DP25: =DN25 | DQ25: =DQ26/DQ24 -> #DIV/0! | DR25: =DN25 | DS25: =DS26/DS24 -> #DIV/0! | DT25: =DN25 | DU25: =DU26/DU24 -> #DIV/0! | DV25: =DN25
C26: Total de reuniões realizadas | D26: =SUM(F26+Q26+AA26+AK26+AU26+BE26+BO26+BY26+CI26+CS26+DC26+DM26) -> 0 | E26: =SUM(G26+R26+AB26+AL26+AV26+BF26+BP26+BZ26+CJ26+CT26+DD26+DN26) -> 5.952381 | F26: =SUM(I26+K26+M26+O26) -> 0 | G26: =G28/G27 -> 0 | H26: =G26/F26 -> #DIV/0! | J26: =G26/4 -> 0 | L26: =G26/4 -> 0 | N26: =G26/4 -> 0 | P26: =G26/4 -> 0 | Q26: =SUM(S26+U26+W26+Y26) -> 0 | T26: =R26/4 -> 0 | V26: =R26/4 -> 0 | X26: =R26/4 -> 0 | Z26: =R26/4 -> 0 | AA26: =SUM(AC26+AE26+AG26+AI26) -> 0 | AD26: =AB26/4 -> 0 | AF26: =AB26/4 -> 0 | AH26: =AB26/4 -> 0 | AJ26: =AB26/4 -> 0 | AK26: =SUM(AM26+AO26+AQ26+AS26) -> 0 | AN26: =AL26/4 -> 0 | AP26: =AL26/4 -> 0 | AR26: =AL26/4 -> 0 | AT26: =AL26/4 -> 0 | AU26: =SUM(AW26+AY26+BA26+BC26) -> 0 | AX26: =AV26/4 -> 0 | AZ26: =AV26/4 -> 0 | BB26: =AV26/4 -> 0 | BD26: =AV26/4 -> 0 | BE26: =SUM(BG26+BI26+BK26+BM26) -> 0 | BF26: =BF28/BF27 -> 5.952381 | BH26: =BF26/4 -> 1.4880952 | BJ26: =BF26/4 -> 1.4880952 | BL26: =BF26/4 -> 1.4880952 | BN26: =BF26/4 -> 1.4880952 | BO26: =SUM(BQ26+BS26+BU26+BW26) -> 0 | BR26: =BP26/4 -> 0 | BT26: =BP26/4 -> 0 | BV26: =BP26/4 -> 0 | BX26: =BP26/4 -> 0 | BY26: =SUM(CA26+CC26+CE26+CG26) -> 0 | CB26: =BZ26/4 -> 0 | CD26: =BZ26/4 -> 0 | CF26: =BZ26/4 -> 0 | CH26: =BZ26/4 -> 0 | CI26: =SUM(CK26+CM26+CO26+CQ26) -> 0 | CL26: =CJ26/4 -> 0 | CN26: =CJ26/4 -> 0 | CP26: =CJ26/4 -> 0 | CR26: =CJ26/4 -> 0 | CS26: =SUM(CU26+CW26+CY26+DA26) -> 0 | CV26: =CT26/4 -> 0 | CX26: =CT26/4 -> 0 | CZ26: =CT26/4 -> 0 | DB26: =CT26/4 -> 0 | DC26: =SUM(DE26+DG26+DI26+DK26) -> 0 | DF26: =DD26/4 -> 0 | DH26: =DD26/4 -> 0 | DJ26: =DD26/4 -> 0 | DL26: =DD26/4 -> 0 | DM26: =SUM(DO26+DQ26+DS26+DU26) -> 0 | DP26: =DN26/4 -> 0 | DR26: =DN26/4 -> 0 | DT26: =DN26/4 -> 0 | DV26: =DN26/4 -> 0
C27: % de propostas apresentadas | D27: =D28/D26 -> #DIV/0! | E27: =E28/E26 -> 0.7 | F27: =F28/F26 -> #DIV/0! | G27: 0.8 | H27: - | I27: =I28/I26 -> #DIV/0! | J27: =G27 -> 0.8 | K27: =K28/K26 -> #DIV/0! | L27: =G27 -> 0.8 | M27: =M28/M26 -> #DIV/0! | N27: =G27 -> 0.8 | O27: =O28/O26 -> #DIV/0! | P27: =G27 -> 0.8 | Q27: =Q28/Q26 -> #DIV/0! | S27: =S28/S26 -> #DIV/0! | T27: =R27 | U27: =U28/U26 -> #DIV/0! | V27: =R27 | W27: =W28/W26 -> #DIV/0! | X27: =R27 | Y27: =Y28/Y26 -> #DIV/0! | Z27: =R27 | AA27: =AA28/AA26 -> #DIV/0! | AC27: =AC28/AC26 -> #DIV/0! | AD27: =AB27 | AE27: =AE28/AE26 -> #DIV/0! | AF27: =AB27 | AG27: =AG28/AG26 -> #DIV/0! | AH27: =AB27 | AI27: =AI28/AI26 -> #DIV/0! | AJ27: =AB27 | AK27: =AK28/AK26 -> #DIV/0! | AM27: =AM28/AM26 -> #DIV/0! | AN27: =AL27 | AO27: =AO28/AO26 -> #DIV/0! | AP27: =AL27 | AQ27: =AQ28/AQ26 -> #DIV/0! | AR27: =AL27 | AS27: =AS28/AS26 -> #DIV/0! | AT27: =AL27 | AU27: =AU28/AU26 -> #DIV/0! | AW27: =AW28/AW26 -> #DIV/0! | AX27: =AV27 | AY27: =AY28/AY26 -> #DIV/0! | AZ27: =AV27 | BA27: =BA28/BA26 -> #DIV/0! | BB27: =AV27 | BC27: =BC28/BC26 -> #DIV/0! | BD27: =AV27 | BE27: =BE28/BE26 -> #DIV/0! | BF27: 0.7 | BG27: =BG28/BG26 -> #DIV/0! | BH27: =BF27 -> 0.7 | BI27: =BI28/BI26 -> #DIV/0! | BJ27: =BF27 -> 0.7 | BK27: =BK28/BK26 -> #DIV/0! | BL27: =BF27 -> 0.7 | BM27: =BM28/BM26 -> #DIV/0! | BN27: =BF27 -> 0.7 | BO27: =BO28/BO26 -> #DIV/0! | BQ27: =BQ28/BQ26 -> #DIV/0! | BR27: =BP27 | BS27: =BS28/BS26 -> #DIV/0! | BT27: =BP27 | BU27: =BU28/BU26 -> #DIV/0! | BV27: =BP27 | BW27: =BW28/BW26 -> #DIV/0! | BX27: =BP27 | BY27: =BY28/BY26 -> #DIV/0! | CA27: =CA28/CA26 -> #DIV/0! | CB27: =BZ27 | CC27: =CC28/CC26 -> #DIV/0! | CD27: =BZ27 | CE27: =CE28/CE26 -> #DIV/0! | CF27: =BZ27 | CG27: =CG28/CG26 -> #DIV/0! | CH27: =BZ27 | CI27: =CI28/CI26 -> #DIV/0! | CK27: =CK28/CK26 -> #DIV/0! | CL27: =CJ27 | CM27: =CM28/CM26 -> #DIV/0! | CN27: =CJ27 | CO27: =CO28/CO26 -> #DIV/0! | CP27: =CJ27 | CQ27: =CQ28/CQ26 -> #DIV/0! | CR27: =CJ27 | CS27: =CS28/CS26 -> #DIV/0! | CU27: =CU28/CU26 -> #DIV/0! | CV27: =CT27 | CW27: =CW28/CW26 -> #DIV/0! | CX27: =CT27 | CY27: =CY28/CY26 -> #DIV/0! | CZ27: =CT27 | DA27: =DA28/DA26 -> #DIV/0! | DB27: =CT27 | DC27: =DC28/DC26 -> #DIV/0! | DE27: =DE28/DE26 -> #DIV/0! | DF27: =DD27 | DG27: =DG28/DG26 -> #DIV/0! | DH27: =DD27 | DI27: =DI28/DI26 -> #DIV/0! | DJ27: =DD27 | DK27: =DK28/DK26 -> #DIV/0! | DL27: =DD27 | DM27: =DM28/DM26 -> #DIV/0! | DO27: =DO28/DO26 -> #DIV/0! | DP27: =DN27 | DQ27: =DQ28/DQ26 -> #DIV/0! | DR27: =DN27 | DS27: =DS28/DS26 -> #DIV/0! | DT27: =DN27 | DU27: =DU28/DU26 -> #DIV/0! | DV27: =DN27
C28: Total de propostas apresentadas | D28: =SUM(F28+Q28+AA28+AK28+AU28+BE28+BO28+BY28+CI28+CS28+DC28+DM28) -> 0 | E28: =SUM(G28+R28+AB28+AL28+AV28+BF28+BP28+BZ28+CJ28+CT28+DD28+DN28) -> 4.1666667 | F28: =SUM(I28+K28+M28+O28) -> 0 | G28: =G30/G29 -> 0 | H28: =G28/F28 -> #DIV/0! | J28: =G28/4 -> 0 | L28: =G28/4 -> 0 | N28: =G28/4 -> 0 | P28: =G28/4 -> 0 | Q28: =SUM(S28+U28+W28+Y28) -> 0 | T28: =R28/4 -> 0 | V28: =R28/4 -> 0 | X28: =R28/4 -> 0 | Z28: =R28/4 -> 0 | AA28: =SUM(AC28+AE28+AG28+AI28) -> 0 | AD28: =AB28/4 -> 0 | AF28: =AB28/4 -> 0 | AH28: =AB28/4 -> 0 | AJ28: =AB28/4 -> 0 | AK28: =SUM(AM28+AO28+AQ28+AS28) -> 0 | AN28: =AL28/4 -> 0 | AP28: =AL28/4 -> 0 | AR28: =AL28/4 -> 0 | AT28: =AL28/4 -> 0 | AU28: =SUM(AW28+AY28+BA28+BC28) -> 0 | AX28: =AV28/4 -> 0 | AZ28: =AV28/4 -> 0 | BB28: =AV28/4 -> 0 | BD28: =AV28/4 -> 0 | BE28: =SUM(BG28+BI28+BK28+BM28) -> 0 | BF28: =BF30/BF29 -> 4.1666667 | BH28: =BF28/4 -> 1.0416667 | BJ28: =BF28/4 -> 1.0416667 | BL28: =BF28/4 -> 1.0416667 | BN28: =BF28/4 -> 1.0416667 | BO28: =SUM(BQ28+BS28+BU28+BW28) -> 0 | BR28: =BP28/4 -> 0 | BT28: =BP28/4 -> 0 | BV28: =BP28/4 -> 0 | BX28: =BP28/4 -> 0 | BY28: =SUM(CA28+CC28+CE28+CG28) -> 0 | CB28: =BZ28/4 -> 0 | CD28: =BZ28/4 -> 0 | CF28: =BZ28/4 -> 0 | CH28: =BZ28/4 -> 0 | CI28: =SUM(CK28+CM28+CO28+CQ28) -> 0 | CL28: =CJ28/4 -> 0 | CN28: =CJ28/4 -> 0 | CP28: =CJ28/4 -> 0 | CR28: =CJ28/4 -> 0 | CS28: =SUM(CU28+CW28+CY28+DA28) -> 0 | CV28: =CT28/4 -> 0 | CX28: =CT28/4 -> 0 | CZ28: =CT28/4 -> 0 | DB28: =CT28/4 -> 0 | DC28: =SUM(DE28+DG28+DI28+DK28) -> 0 | DF28: =DD28/4 -> 0 | DH28: =DD28/4 -> 0 | DJ28: =DD28/4 -> 0 | DL28: =DD28/4 -> 0 | DM28: =SUM(DO28+DQ28+DS28+DU28) -> 0 | DP28: =DN28/4 -> 0 | DR28: =DN28/4 -> 0 | DT28: =DN28/4 -> 0 | DV28: =DN28/4 -> 0
C29: % de fechamento | D29: =D30/D28 -> #DIV/0! | E29: =E30/E28 -> 0.4 | F29: =F30/F28 -> #DIV/0! | G29: 0.4 | H29: - | I29: =I30/I28 -> #DIV/0! | J29: =G29 -> 0.4 | K29: =K30/K28 -> #DIV/0! | L29: =G29 -> 0.4 | M29: =M30/M28 -> #DIV/0! | N29: =G29 -> 0.4 | O29: =O30/O28 -> #DIV/0! | P29: =G29 -> 0.4 | Q29: =Q30/Q28 -> #DIV/0! | S29: =S30/S28 -> #DIV/0! | T29: =R29 | U29: =U30/U28 -> #DIV/0! | V29: =R29 | W29: =W30/W28 -> #DIV/0! | X29: =R29 | Y29: =Y30/Y28 -> #DIV/0! | Z29: =R29 | AA29: =AA30/AA28 -> #DIV/0! | AC29: =AC30/AC28 -> #DIV/0! | AD29: =AB29 | AE29: =AE30/AE28 -> #DIV/0! | AF29: =AB29 | AG29: =AG30/AG28 -> #DIV/0! | AH29: =AB29 | AI29: =AI30/AI28 -> #DIV/0! | AJ29: =AB29 | AK29: =AK30/AK28 -> #DIV/0! | AM29: =AM30/AM28 -> #DIV/0! | AN29: =AL29 | AO29: =AO30/AO28 -> #DIV/0! | AP29: =AL29 | AQ29: =AQ30/AQ28 -> #DIV/0! | AR29: =AL29 | AS29: =AS30/AS28 -> #DIV/0! | AT29: =AL29 | AU29: =AU30/AU28 -> #DIV/0! | AW29: =AW30/AW28 -> #DIV/0! | AX29: =AV29 | AY29: =AY30/AY28 -> #DIV/0! | AZ29: =AV29 | BA29: =BA30/BA28 -> #DIV/0! | BB29: =AV29 | BC29: =BC30/BC28 -> #DIV/0! | BD29: =AV29 | BE29: =BE30/BE28 -> #DIV/0! | BF29: 0.4 | BG29: =BG30/BG28 -> #DIV/0! | BH29: =BF29 -> 0.4 | BI29: =BI30/BI28 -> #DIV/0! | BJ29: =BF29 -> 0.4 | BK29: =BK30/BK28 -> #DIV/0! | BL29: =BF29 -> 0.4 | BM29: =BM30/BM28 -> #DIV/0! | BN29: =BF29 -> 0.4 | BO29: =BO30/BO28 -> #DIV/0! | BQ29: =BQ30/BQ28 -> #DIV/0! | BR29: =BP29 | BS29: =BS30/BS28 -> #DIV/0! | BT29: =BP29 | BU29: =BU30/BU28 -> #DIV/0! | BV29: =BP29 | BW29: =BW30/BW28 -> #DIV/0! | BX29: =BP29 | BY29: =BY30/BY28 -> #DIV/0! | CA29: =CA30/CA28 -> #DIV/0! | CB29: =BZ29 | CC29: =CC30/CC28 -> #DIV/0! | CD29: =BZ29 | CE29: =CE30/CE28 -> #DIV/0! | CF29: =BZ29 | CG29: =CG30/CG28 -> #DIV/0! | CH29: =BZ29 | CI29: =CI30/CI28 -> #DIV/0! | CK29: =CK30/CK28 -> #DIV/0! | CL29: =CJ29 | CM29: =CM30/CM28 -> #DIV/0! | CN29: =CJ29 | CO29: =CO30/CO28 -> #DIV/0! | CP29: =CJ29 | CQ29: =CQ30/CQ28 -> #DIV/0! | CR29: =CJ29 | CS29: =CS30/CS28 -> #DIV/0! | CU29: =CU30/CU28 -> #DIV/0! | CV29: =CT29 | CW29: =CW30/CW28 -> #DIV/0! | CX29: =CT29 | CY29: =CY30/CY28 -> #DIV/0! | CZ29: =CT29 | DA29: =DA30/DA28 -> #DIV/0! | DB29: =CT29 | DC29: =DC30/DC28 -> #DIV/0! | DE29: =DE30/DE28 -> #DIV/0! | DF29: =DD29 | DG29: =DG30/DG28 -> #DIV/0! | DH29: =DD29 | DI29: =DI30/DI28 -> #DIV/0! | DJ29: =DD29 | DK29: =DK30/DK28 -> #DIV/0! | DL29: =DD29 | DM29: =DM30/DM28 -> #DIV/0! | DO29: =DO30/DO28 -> #DIV/0! | DP29: =DN29 | DQ29: =DQ30/DQ28 -> #DIV/0! | DR29: =DN29 | DS29: =DS30/DS28 -> #DIV/0! | DT29: =DN29 | DU29: =DU30/DU28 -> #DIV/0! | DV29: =DN29
C30: Total de propostas fechadas | D30: =SUM(F30+Q30+AA30+AK30+AU30+BE30+BO30+BY30+CI30+CS30+DC30+DM30) -> 0 | E30: =SUM(G30+R30+AB30+AL30+AV30+BF30+BP30+BZ30+CJ30+CT30+DD30+DN30) -> 1.6666667 | F30: =SUM(I30+K30+M30+O30) -> 0 | G30: ='Dados da Operação'!H27 -> 0 | H30: =G30/F30 -> #DIV/0! | J30: =G30/4 -> 0 | L30: =G30/4 -> 0 | N30: =G30/4 -> 0 | P30: =G30/4 -> 0 | Q30: =SUM(S30+U30+W30+Y30) -> 0 | R30: ='Dados da Operação'!H36 -> 0 | T30: =R30/4 -> 0 | V30: =R30/4 -> 0 | X30: =R30/4 -> 0 | Z30: =R30/4 -> 0 | AA30: =SUM(AC30+AE30+AG30+AI30) -> 0 | AB30: ='Dados da Operação'!H45 -> 0 | AD30: =AB30/4 -> 0 | AF30: =AB30/4 -> 0 | AH30: =AB30/4 -> 0 | AJ30: =AB30/4 -> 0 | AK30: =SUM(AM30+AO30+AQ30+AS30) -> 0 | AL30: ='Dados da Operação'!H54 -> 0 | AN30: =AL30/4 -> 0 | AP30: =AL30/4 -> 0 | AR30: =AL30/4 -> 0 | AT30: =AL30/4 -> 0 | AU30: =SUM(AW30+AY30+BA30+BC30) -> 0 | AV30: ='Dados da Operação'!H63 -> 0 | AX30: =AV30/4 -> 0 | AZ30: =AV30/4 -> 0 | BB30: =AV30/4 -> 0 | BD30: =AV30/4 -> 0 | BE30: =SUM(BG30+BI30+BK30+BM30) -> 0 | BF30: ='Dados da Operação'!J4 -> 1.6666667 | BH30: =BF30/4 -> 0.41666667 | BJ30: =BF30/4 -> 0.41666667 | BL30: =BF30/4 -> 0.41666667 | BN30: =BF30/4 -> 0.41666667 | BO30: =SUM(BQ30+BS30+BU30+BW30) -> 0 | BP30: ='Dados da Operação'!H81 -> 0 | BR30: =BP30/4 -> 0 | BT30: =BP30/4 -> 0 | BV30: =BP30/4 -> 0 | BX30: =BP30/4 -> 0 | BY30: =SUM(CA30+CC30+CE30+CG30) -> 0 | BZ30: ='Dados da Operação'!H90 -> 0 | CB30: =BZ30/4 -> 0 | CD30: =BZ30/4 -> 0 | CF30: =BZ30/4 -> 0 | CH30: =BZ30/4 -> 0 | CI30: =SUM(CK30+CM30+CO30+CQ30) -> 0 | CJ30: ='Dados da Operação'!H99 -> 0 | CL30: =CJ30/4 -> 0 | CN30: =CJ30/4 -> 0 | CP30: =CJ30/4 -> 0 | CR30: =CJ30/4 -> 0 | CS30: =SUM(CU30+CW30+CY30+DA30) -> 0 | CT30: ='Dados da Operação'!H108 -> 0 | CV30: =CT30/4 -> 0 | CX30: =CT30/4 -> 0 | CZ30: =CT30/4 -> 0 | DB30: =CT30/4 -> 0 | DC30: =SUM(DE30+DG30+DI30+DK30) -> 0 | DD30: ='Dados da Operação'!H117 -> 0 | DF30: =DD30/4 -> 0 | DH30: =DD30/4 -> 0 | DJ30: =DD30/4 -> 0 | DL30: =DD30/4 -> 0 | DM30: =SUM(DO30+DQ30+DS30+DU30) -> 0 | DN30: ='Dados da Operação'!H126 -> 0 | DP30: =DN30/4 -> 0 | DR30: =DN30/4 -> 0 | DT30: =DN30/4 -> 0 | DV30: =DN30/4 -> 0
C31: Total de faturamento | D31: =SUM(F31+Q31+AA31+AK31+AU31+BE31+BO31+BY31+CI31+CS31+DC31+DM31) -> 0 | E31: =SUM(G31+R31+AB31+AL31+AV31+BF31+BP31+BZ31+CJ31+CT31+DD31+DN31) -> 4166.6667 | F31: =SUM(I31+K31+M31+O31) -> 0 | G31: ='Dados da Operação'!G27 -> 0 | H31: =G31/F31 -> #DIV/0! | J31: =G31/4 -> 0 | L31: =G31/4 -> 0 | N31: =G31/4 -> 0 | P31: =G31/4 -> 0 | Q31: =SUM(S31+U31+W31+Y31) -> 0 | R31: ='Dados da Operação'!G36 -> 0 | T31: =R31/4 -> 0 | V31: =R31/4 -> 0 | X31: =R31/4 -> 0 | Z31: =R31/4 -> 0 | AA31: =SUM(AC31+AE31+AG31+AI31) -> 0 | AB31: ='Dados da Operação'!G45 -> 0 | AD31: =AB31/4 -> 0 | AF31: =AB31/4 -> 0 | AH31: =AB31/4 -> 0 | AJ31: =AB31/4 -> 0 | AK31: =SUM(AM31+AO31+AQ31+AS31) -> 0 | AL31: ='Dados da Operação'!G54 -> 0 | AN31: =AL31/4 -> 0 | AP31: =AL31/4 -> 0 | AR31: =AL31/4 -> 0 | AT31: =AL31/4 -> 0 | AU31: =SUM(AW31+AY31+BA31+BC31) -> 0 | AV31: ='Dados da Operação'!G63 -> 0 | AX31: =AV31/4 -> 0 | AZ31: =AV31/4 -> 0 | BB31: =AV31/4 -> 0 | BD31: =AV31/4 -> 0 | BE31: =SUM(BG31+BI31+BK31+BM31) -> 0 | BF31: =BF32*BF30 -> 4166.6667 | BH31: =BF31/4 -> 1041.6667 | BJ31: =BF31/4 -> 1041.6667 | BL31: =BF31/4 -> 1041.6667 | BN31: =BF31/4 -> 1041.6667 | BO31: =SUM(BQ31+BS31+BU31+BW31) -> 0 | BP31: ='Dados da Operação'!G81 -> 0 | BR31: =BP31/4 -> 0 | BT31: =BP31/4 -> 0 | BV31: =BP31/4 -> 0 | BX31: =BP31/4 -> 0 | BY31: =SUM(CA31+CC31+CE31+CG31) -> 0 | BZ31: ='Dados da Operação'!G90 -> 0 | CB31: =BZ31/4 -> 0 | CD31: =BZ31/4 -> 0 | CF31: =BZ31/4 -> 0 | CH31: =BZ31/4 -> 0 | CI31: =SUM(CK31+CM31+CO31+CQ31) -> 0 | CJ31: ='Dados da Operação'!G99 -> 0 | CL31: =CJ31/4 -> 0 | CN31: =CJ31/4 -> 0 | CP31: =CJ31/4 -> 0 | CR31: =CJ31/4 -> 0 | CS31: =SUM(CU31+CW31+CY31+DA31) -> 0 | CT31: ='Dados da Operação'!G108 -> 0 | CV31: =CT31/4 -> 0 | CX31: =CT31/4 -> 0 | CZ31: =CT31/4 -> 0 | DB31: =CT31/4 -> 0 | DC31: =SUM(DE31+DG31+DI31+DK31) -> 0 | DD31: ='Dados da Operação'!G117 -> 0 | DF31: =DD31/4 -> 0 | DH31: =DD31/4 -> 0 | DJ31: =DD31/4 -> 0 | DL31: =DD31/4 -> 0 | DM31: =SUM(DO31+DQ31+DS31+DU31) -> 0 | DN31: ='Dados da Operação'!G126 -> 0 | DP31: =DN31/4 -> 0 | DR31: =DN31/4 -> 0 | DT31: =DN31/4 -> 0 | DV31: =DN31/4 -> 0
C32: Ticket médio | D32: =D31/D30 -> #DIV/0! | E32: =E31/E30 -> 2500 | F32: =F31/F30 -> #DIV/0! | G32: ='Dados da Operação'!$C$5 -> 2500 | H32: =G32/F32 -> #DIV/0! | I32: =I31/I30 -> #DIV/0! | J32: =G32 -> 2500 | K32: =K31/K30 -> #DIV/0! | L32: =G32 -> 2500 | M32: =M31/M30 -> #DIV/0! | N32: =G32 -> 2500 | O32: =O31/O30 -> #DIV/0! | P32: =G32 -> 2500 | Q32: =Q31/Q30 -> #DIV/0! | R32: ='Dados da Operação'!$C$5 -> 2500 | S32: =S31/S30 -> #DIV/0! | T32: =R32 -> 2500 | U32: =U31/U30 -> #DIV/0! | V32: =R32 -> 2500 | W32: =W31/W30 -> #DIV/0! | X32: =R32 -> 2500 | Y32: =Y31/Y30 -> #DIV/0! | Z32: =R32 -> 2500 | AA32: =AA31/AA30 -> #DIV/0! | AB32: ='Dados da Operação'!$C$5 -> 2500 | AC32: =AC31/AC30 -> #DIV/0! | AD32: =AB32 -> 2500 | AE32: =AE31/AE30 -> #DIV/0! | AF32: =AB32 -> 2500 | AG32: =AG31/AG30 -> #DIV/0! | AH32: =AB32 -> 2500 | AI32: =AI31/AI30 -> #DIV/0! | AJ32: =AB32 -> 2500 | AK32: =AK31/AK30 -> #DIV/0! | AL32: ='Dados da Operação'!$C$5 -> 2500 | AM32: =AM31/AM30 -> #DIV/0! | AN32: =AL32 -> 2500 | AO32: =AO31/AO30 -> #DIV/0! | AP32: =AL32 -> 2500 | AQ32: =AQ31/AQ30 -> #DIV/0! | AR32: =AL32 -> 2500 | AS32: =AS31/AS30 -> #DIV/0! | AT32: =AL32 -> 2500 | AU32: =AU31/AU30 -> #DIV/0! | AV32: ='Dados da Operação'!$C$5 -> 2500 | AW32: =AW31/AW30 -> #DIV/0! | AX32: =AV32 -> 2500 | AY32: =AY31/AY30 -> #DIV/0! | AZ32: =AV32 -> 2500 | BA32: =BA31/BA30 -> #DIV/0! | BB32: =AV32 -> 2500 | BC32: =BC31/BC30 -> #DIV/0! | BD32: =AV32 -> 2500 | BE32: =BE31/BE30 -> #DIV/0! | BF32: ='Dados da Operação'!$C$5 -> 2500 | BG32: =BG31/BG30 -> #DIV/0! | BH32: =BF32 -> 2500 | BI32: =BI31/BI30 -> #DIV/0! | BJ32: =BF32 -> 2500 | BK32: =BK31/BK30 -> #DIV/0! | BL32: =BF32 -> 2500 | BM32: =BM31/BM30 -> #DIV/0! | BN32: =BF32 -> 2500 | BO32: =BO31/BO30 -> #DIV/0! | BP32: ='Dados da Operação'!$C$5 -> 2500 | BQ32: =BQ31/BQ30 -> #DIV/0! | BR32: =BP32 -> 2500 | BS32: =BS31/BS30 -> #DIV/0! | BT32: =BP32 -> 2500 | BU32: =BU31/BU30 -> #DIV/0! | BV32: =BP32 -> 2500 | BW32: =BW31/BW30 -> #DIV/0! | BX32: =BP32 -> 2500 | BY32: =BY31/BY30 -> #DIV/0! | BZ32: ='Dados da Operação'!$C$5 -> 2500 | CA32: =CA31/CA30 -> #DIV/0! | CB32: =BZ32 -> 2500 | CC32: =CC31/CC30 -> #DIV/0! | CD32: =BZ32 -> 2500 | CE32: =CE31/CE30 -> #DIV/0! | CF32: =BZ32 -> 2500 | CG32: =CG31/CG30 -> #DIV/0! | CH32: =BZ32 -> 2500 | CI32: =CI31/CI30 -> #DIV/0! | CJ32: ='Dados da Operação'!$C$5 -> 2500 | CK32: =CK31/CK30 -> #DIV/0! | CL32: =CJ32 -> 2500 | CM32: =CM31/CM30 -> #DIV/0! | CN32: =CJ32 -> 2500 | CO32: =CO31/CO30 -> #DIV/0! | CP32: =CJ32 -> 2500 | CQ32: =CQ31/CQ30 -> #DIV/0! | CR32: =CJ32 -> 2500 | CS32: =CS31/CS30 -> #DIV/0! | CT32: ='Dados da Operação'!$C$5 -> 2500 | CU32: =CU31/CU30 -> #DIV/0! | CV32: =CT32 -> 2500 | CW32: =CW31/CW30 -> #DIV/0! | CX32: =CT32 -> 2500 | CY32: =CY31/CY30 -> #DIV/0! | CZ32: =CT32 -> 2500 | DA32: =DA31/DA30 -> #DIV/0! | DB32: =CT32 -> 2500 | DC32: =DC31/DC30 -> #DIV/0! | DD32: ='Dados da Operação'!$C$5 -> 2500 | DE32: =DE31/DE30 -> #DIV/0! | DF32: =DD32 -> 2500 | DG32: =DG31/DG30 -> #DIV/0! | DH32: =DD32 -> 2500 | DI32: =DI31/DI30 -> #DIV/0! | DJ32: =DD32 -> 2500 | DK32: =DK31/DK30 -> #DIV/0! | DL32: =DD32 -> 2500 | DM32: =DM31/DM30 -> #DIV/0! | DN32: ='Dados da Operação'!$C$5 -> 2500 | DO32: =DO31/DO30 -> #DIV/0! | DP32: =DN32 -> 2500 | DQ32: =DQ31/DQ30 -> #DIV/0! | DR32: =DN32 -> 2500 | DS32: =DS31/DS30 -> #DIV/0! | DT32: =DN32 -> 2500 | DU32: =DU31/DU30 -> #DIV/0! | DV32: =DN32 -> 2500
B34: INBOUND | C34: Total de leads captados | D34: =SUM(F34+Q34+AA34+AK34+AU34+BE34+BO34+BY34+CI34+CS34+DC34+DM34) -> 0 | E34: =SUM(G34+R34+AB34+AL34+AV34+BF34+BP34+BZ34+CJ34+CT34+DD34+DN34) -> 0 | F34: =SUM(I34+K34+M34+O34) -> 0 | G34: =G36/G35 -> 0 | H34: =F34/G34 -> #DIV/0! | J34: =G34/4 -> 0 | L34: =G34/4 -> 0 | N34: =G34/4 -> 0 | P34: =G34/4 -> 0 | Q34: =SUM(S34+U34+W34+Y34) -> 0 | R34: =R36/R35 -> 0 | T34: =R34/4 -> 0 | V34: =R34/4 -> 0 | X34: =R34/4 -> 0 | Z34: =R34/4 -> 0 | AA34: =SUM(AC34+AE34+AG34+AI34) -> 0 | AB34: =AB36/AB35 -> 0 | AD34: =AB34/4 -> 0 | AF34: =AB34/4 -> 0 | AH34: =AB34/4 -> 0 | AJ34: =AB34/4 -> 0 | AK34: =SUM(AM34+AO34+AQ34+AS34) -> 0 | AL34: =AL36/AL35 -> 0 | AN34: =AL34/4 -> 0 | AP34: =AL34/4 -> 0 | AR34: =AL34/4 -> 0 | AT34: =AL34/4 -> 0 | AU34: =SUM(AW34+AY34+BA34+BC34) -> 0 | AV34: =AV36/AV35 -> 0 | AX34: =AV34/4 -> 0 | AZ34: =AV34/4 -> 0 | BB34: =AV34/4 -> 0 | BD34: =AV34/4 -> 0 | BE34: =SUM(BG34+BI34+BK34+BM34) -> 0 | BF34: =BF36/BF35 -> 0 | BH34: =BF34/4 -> 0 | BJ34: =BF34/4 -> 0 | BL34: =BF34/4 -> 0 | BN34: =BF34/4 -> 0 | BO34: =SUM(BQ34+BS34+BU34+BW34) -> 0 | BP34: =BP36/BP35 -> 0 | BR34: =BP34/4 -> 0 | BT34: =BP34/4 -> 0 | BV34: =BP34/4 -> 0 | BX34: =BP34/4 -> 0 | BY34: =SUM(CA34+CC34+CE34+CG34) -> 0 | BZ34: =BZ36/BZ35 -> 0 | CB34: =BZ34/4 -> 0 | CD34: =BZ34/4 -> 0 | CF34: =BZ34/4 -> 0 | CH34: =BZ34/4 -> 0 | CI34: =SUM(CK34+CM34+CO34+CQ34) -> 0 | CJ34: =CJ36/CJ35 -> 0 | CL34: =CJ34/4 -> 0 | CN34: =CJ34/4 -> 0 | CP34: =CJ34/4 -> 0 | CR34: =CJ34/4 -> 0 | CS34: =SUM(CU34+CW34+CY34+DA34) -> 0 | CT34: =CT36/CT35 -> 0 | CV34: =CT34/4 -> 0 | CX34: =CT34/4 -> 0 | CZ34: =CT34/4 -> 0 | DB34: =CT34/4 -> 0 | DC34: =SUM(DE34+DG34+DI34+DK34) -> 0 | DD34: =DD36/DD35 -> 0 | DF34: =DD34/4 -> 0 | DH34: =DD34/4 -> 0 | DJ34: =DD34/4 -> 0 | DL34: =DD34/4 -> 0 | DM34: =SUM(DO34+DQ34+DS34+DU34) -> 0 | DN34: =DN36/DN35 -> 0 | DP34: =DN34/4 -> 0 | DR34: =DN34/4 -> 0 | DT34: =DN34/4 -> 0 | DV34: =DN34/4 -> 0
C35: % Conversão em Lead Conectado | D35: =D36/D34 -> #DIV/0! | E35: =E36/E34 -> #DIV/0! | F35: =F36/F34 -> #DIV/0! | G35: 0.6 | H35: - | I35: =I36/I34 -> #DIV/0! | J35: =G35 -> 0.6 | K35: =K36/K34 -> #DIV/0! | L35: =G35 -> 0.6 | M35: =M36/M34 -> #DIV/0! | N35: =G35 -> 0.6 | O35: =O36/O34 -> #DIV/0! | P35: =G35 -> 0.6 | Q35: =Q36/Q34 -> #DIV/0! | R35: 0.6 | S35: =S36/S34 -> #DIV/0! | T35: =R35 -> 0.6 | U35: =U36/U34 -> #DIV/0! | V35: =R35 -> 0.6 | W35: =W36/W34 -> #DIV/0! | X35: =R35 -> 0.6 | Y35: =Y36/Y34 -> #DIV/0! | Z35: =R35 -> 0.6 | AA35: =AA36/AA34 -> #DIV/0! | AB35: 0.6 | AC35: =AC36/AC34 -> #DIV/0! | AD35: =AB35 -> 0.6 | AE35: =AE36/AE34 -> #DIV/0! | AF35: =AB35 -> 0.6 | AG35: =AG36/AG34 -> #DIV/0! | AH35: =AB35 -> 0.6 | AI35: =AI36/AI34 -> #DIV/0! | AJ35: =AB35 -> 0.6 | AK35: =AK36/AK34 -> #DIV/0! | AL35: 0.6 | AM35: =AM36/AM34 -> #DIV/0! | AN35: =AL35 -> 0.6 | AO35: =AO36/AO34 -> #DIV/0! | AP35: =AL35 -> 0.6 | AQ35: =AQ36/AQ34 -> #DIV/0! | AR35: =AL35 -> 0.6 | AS35: =AS36/AS34 -> #DIV/0! | AT35: =AL35 -> 0.6 | AU35: =AU36/AU34 -> #DIV/0! | AV35: 0.6 | AW35: =AW36/AW34 -> #DIV/0! | AX35: =AV35 -> 0.6 | AY35: =AY36/AY34 -> #DIV/0! | AZ35: =AV35 -> 0.6 | BA35: =BA36/BA34 -> #DIV/0! | BB35: =AV35 -> 0.6 | BC35: =BC36/BC34 -> #DIV/0! | BD35: =AV35 -> 0.6 | BE35: =BE36/BE34 -> #DIV/0! | BF35: 0.25 | BG35: =BG36/BG34 -> #DIV/0! | BH35: =BF35 -> 0.25 | BI35: =BI36/BI34 -> #DIV/0! | BJ35: =BF35 -> 0.25 | BK35: =BK36/BK34 -> #DIV/0! | BL35: =BF35 -> 0.25 | BM35: =BM36/BM34 -> #DIV/0! | BN35: =BF35 -> 0.25 | BO35: =BO36/BO34 -> #DIV/0! | BP35: 0.6 | BQ35: =BQ36/BQ34 -> #DIV/0! | BR35: =BP35 -> 0.6 | BS35: =BS36/BS34 -> #DIV/0! | BT35: =BP35 -> 0.6 | BU35: =BU36/BU34 -> #DIV/0! | BV35: =BP35 -> 0.6 | BW35: =BW36/BW34 -> #DIV/0! | BX35: =BP35 -> 0.6 | BY35: =BY36/BY34 -> #DIV/0! | BZ35: 0.6 | CA35: =CA36/CA34 -> #DIV/0! | CB35: =BZ35 -> 0.6 | CC35: =CC36/CC34 -> #DIV/0! | CD35: =BZ35 -> 0.6 | CE35: =CE36/CE34 -> #DIV/0! | CF35: =BZ35 -> 0.6 | CG35: =CG36/CG34 -> #DIV/0! | CH35: =BZ35 -> 0.6 | CI35: =CI36/CI34 -> #DIV/0! | CJ35: 0.6 | CK35: =CK36/CK34 -> #DIV/0! | CL35: =CJ35 -> 0.6 | CM35: =CM36/CM34 -> #DIV/0! | CN35: =CJ35 -> 0.6 | CO35: =CO36/CO34 -> #DIV/0! | CP35: =CJ35 -> 0.6 | CQ35: =CQ36/CQ34 -> #DIV/0! | CR35: =CJ35 -> 0.6 | CS35: =CS36/CS34 -> #DIV/0! | CT35: 0.6 | CU35: =CU36/CU34 -> #DIV/0! | CV35: =CT35 -> 0.6 | CW35: =CW36/CW34 -> #DIV/0! | CX35: =CT35 -> 0.6 | CY35: =CY36/CY34 -> #DIV/0! | CZ35: =CT35 -> 0.6 | DA35: =DA36/DA34 -> #DIV/0! | DB35: =CT35 -> 0.6 | DC35: =DC36/DC34 -> #DIV/0! | DD35: 0.6 | DE35: =DE36/DE34 -> #DIV/0! | DF35: =DD35 -> 0.6 | DG35: =DG36/DG34 -> #DIV/0! | DH35: =DD35 -> 0.6 | DI35: =DI36/DI34 -> #DIV/0! | DJ35: =DD35 -> 0.6 | DK35: =DK36/DK34 -> #DIV/0! | DL35: =DD35 -> 0.6 | DM35: =DM36/DM34 -> #DIV/0! | DN35: 0.6 | DO35: =DO36/DO34 -> #DIV/0! | DP35: =DN35 -> 0.6 | DQ35: =DQ36/DQ34 -> #DIV/0! | DR35: =DN35 -> 0.6 | DS35: =DS36/DS34 -> #DIV/0! | DT35: =DN35 -> 0.6 | DU35: =DU36/DU34 -> #DIV/0! | DV35: =DN35 -> 0.6
C36: Total de leads conectados | D36: =SUM(F36+Q36+AA36+AK36+AU36+BE36+BO36+BY36+CI36+CS36+DC36+DM36) -> 0 | E36: =SUM(G36+R36+AB36+AL36+AV36+BF36+BP36+BZ36+CJ36+CT36+DD36+DN36) -> 0 | F36: =SUM(I36+K36+M36+O36) -> 0 | G36: =G38/G37 -> 0 | H36: =G36/F36 -> #DIV/0! | J36: =G36/4 -> 0 | L36: =G36/4 -> 0 | N36: =G36/4 -> 0 | P36: =G36/4 -> 0 | Q36: =SUM(S36+U36+W36+Y36) -> 0 | R36: =R38/R37 -> 0 | T36: =R36/4 -> 0 | V36: =R36/4 -> 0 | X36: =R36/4 -> 0 | Z36: =R36/4 -> 0 | AA36: =SUM(AC36+AE36+AG36+AI36) -> 0 | AB36: =AB38/AB37 -> 0 | AD36: =AB36/4 -> 0 | AF36: =AB36/4 -> 0 | AH36: =AB36/4 -> 0 | AJ36: =AB36/4 -> 0 | AK36: =SUM(AM36+AO36+AQ36+AS36) -> 0 | AL36: =AL38/AL37 -> 0 | AN36: =AL36/4 -> 0 | AP36: =AL36/4 -> 0 | AR36: =AL36/4 -> 0 | AT36: =AL36/4 -> 0 | AU36: =SUM(AW36+AY36+BA36+BC36) -> 0 | AV36: =AV38/AV37 -> 0 | AX36: =AV36/4 -> 0 | AZ36: =AV36/4 -> 0 | BB36: =AV36/4 -> 0 | BD36: =AV36/4 -> 0 | BE36: =SUM(BG36+BI36+BK36+BM36) -> 0 | BF36: =BF38/BF37 -> 0 | BH36: =BF36/4 -> 0 | BJ36: =BF36/4 -> 0 | BL36: =BF36/4 -> 0 | BN36: =BF36/4 -> 0 | BO36: =SUM(BQ36+BS36+BU36+BW36) -> 0 | BP36: =BP38/BP37 -> 0 | BR36: =BP36/4 -> 0 | BT36: =BP36/4 -> 0 | BV36: =BP36/4 -> 0 | BX36: =BP36/4 -> 0 | BY36: =SUM(CA36+CC36+CE36+CG36) -> 0 | BZ36: =BZ38/BZ37 -> 0 | CB36: =BZ36/4 -> 0 | CD36: =BZ36/4 -> 0 | CF36: =BZ36/4 -> 0 | CH36: =BZ36/4 -> 0 | CI36: =SUM(CK36+CM36+CO36+CQ36) -> 0 | CJ36: =CJ38/CJ37 -> 0 | CL36: =CJ36/4 -> 0 | CN36: =CJ36/4 -> 0 | CP36: =CJ36/4 -> 0 | CR36: =CJ36/4 -> 0 | CS36: =SUM(CU36+CW36+CY36+DA36) -> 0 | CT36: =CT38/CT37 -> 0 | CV36: =CT36/4 -> 0 | CX36: =CT36/4 -> 0 | CZ36: =CT36/4 -> 0 | DB36: =CT36/4 -> 0 | DC36: =SUM(DE36+DG36+DI36+DK36) -> 0 | DD36: =DD38/DD37 -> 0 | DF36: =DD36/4 -> 0 | DH36: =DD36/4 -> 0 | DJ36: =DD36/4 -> 0 | DL36: =DD36/4 -> 0 | DM36: =SUM(DO36+DQ36+DS36+DU36) -> 0 | DN36: =DN38/DN37 -> 0 | DP36: =DN36/4 -> 0 | DR36: =DN36/4 -> 0 | DT36: =DN36/4 -> 0 | DV36: =DN36/4 -> 0
C37: % Conversão em Reunião agendada | D37: =D38/D36 -> #DIV/0! | E37: =E38/E36 -> #DIV/0! | F37: =F38/F36 -> #DIV/0! | G37: 0.4 | H37: - | I37: =I38/I36 -> #DIV/0! | J37: =G37 -> 0.4 | K37: =K38/K36 -> #DIV/0! | L37: =G37 -> 0.4 | M37: =M38/M36 -> #DIV/0! | N37: =G37 -> 0.4 | O37: =O38/O36 -> #DIV/0! | P37: =G37 -> 0.4 | Q37: =Q38/Q36 -> #DIV/0! | R37: 0.4 | S37: =S38/S36 -> #DIV/0! | T37: =R37 -> 0.4 | U37: =U38/U36 -> #DIV/0! | V37: =R37 -> 0.4 | W37: =W38/W36 -> #DIV/0! | X37: =R37 -> 0.4 | Y37: =Y38/Y36 -> #DIV/0! | Z37: =R37 -> 0.4 | AA37: =AA38/AA36 -> #DIV/0! | AB37: 0.4 | AC37: =AC38/AC36 -> #DIV/0! | AD37: =AB37 -> 0.4 | AE37: =AE38/AE36 -> #DIV/0! | AF37: =AB37 -> 0.4 | AG37: =AG38/AG36 -> #DIV/0! | AH37: =AB37 -> 0.4 | AI37: =AI38/AI36 -> #DIV/0! | AJ37: =AB37 -> 0.4 | AK37: =AK38/AK36 -> #DIV/0! | AL37: 0.4 | AM37: =AM38/AM36 -> #DIV/0! | AN37: =AL37 -> 0.4 | AO37: =AO38/AO36 -> #DIV/0! | AP37: =AL37 -> 0.4 | AQ37: =AQ38/AQ36 -> #DIV/0! | AR37: =AL37 -> 0.4 | AS37: =AS38/AS36 -> #DIV/0! | AT37: =AL37 -> 0.4 | AU37: =AU38/AU36 -> #DIV/0! | AV37: 0.4 | AW37: =AW38/AW36 -> #DIV/0! | AX37: =AV37 -> 0.4 | AY37: =AY38/AY36 -> #DIV/0! | AZ37: =AV37 -> 0.4 | BA37: =BA38/BA36 -> #DIV/0! | BB37: =AV37 -> 0.4 | BC37: =BC38/BC36 -> #DIV/0! | BD37: =AV37 -> 0.4 | BE37: =BE38/BE36 -> #DIV/0! | BF37: 0.3 | BG37: =BG38/BG36 -> #DIV/0! | BH37: =BF37 -> 0.3 | BI37: =BI38/BI36 -> #DIV/0! | BJ37: =BF37 -> 0.3 | BK37: =BK38/BK36 -> #DIV/0! | BL37: =BF37 -> 0.3 | BM37: =BM38/BM36 -> #DIV/0! | BN37: =BF37 -> 0.3 | BO37: =BO38/BO36 -> #DIV/0! | BP37: 0.4 | BQ37: =BQ38/BQ36 -> #DIV/0! | BR37: =BP37 -> 0.4 | BS37: =BS38/BS36 -> #DIV/0! | BT37: =BP37 -> 0.4 | BU37: =BU38/BU36 -> #DIV/0! | BV37: =BP37 -> 0.4 | BW37: =BW38/BW36 -> #DIV/0! | BX37: =BP37 -> 0.4 | BY37: =BY38/BY36 -> #DIV/0! | BZ37: 0.4 | CA37: =CA38/CA36 -> #DIV/0! | CB37: =BZ37 -> 0.4 | CC37: =CC38/CC36 -> #DIV/0! | CD37: =BZ37 -> 0.4 | CE37: =CE38/CE36 -> #DIV/0! | CF37: =BZ37 -> 0.4 | CG37: =CG38/CG36 -> #DIV/0! | CH37: =BZ37 -> 0.4 | CI37: =CI38/CI36 -> #DIV/0! | CJ37: 0.4 | CK37: =CK38/CK36 -> #DIV/0! | CL37: =CJ37 -> 0.4 | CM37: =CM38/CM36 -> #DIV/0! | CN37: =CJ37 -> 0.4 | CO37: =CO38/CO36 -> #DIV/0! | CP37: =CJ37 -> 0.4 | CQ37: =CQ38/CQ36 -> #DIV/0! | CR37: =CJ37 -> 0.4 | CS37: =CS38/CS36 -> #DIV/0! | CT37: 0.4 | CU37: =CU38/CU36 -> #DIV/0! | CV37: =CT37 -> 0.4 | CW37: =CW38/CW36 -> #DIV/0! | CX37: =CT37 -> 0.4 | CY37: =CY38/CY36 -> #DIV/0! | CZ37: =CT37 -> 0.4 | DA37: =DA38/DA36 -> #DIV/0! | DB37: =CT37 -> 0.4 | DC37: =DC38/DC36 -> #DIV/0! | DD37: 0.4 | DE37: =DE38/DE36 -> #DIV/0! | DF37: =DD37 -> 0.4 | DG37: =DG38/DG36 -> #DIV/0! | DH37: =DD37 -> 0.4 | DI37: =DI38/DI36 -> #DIV/0! | DJ37: =DD37 -> 0.4 | DK37: =DK38/DK36 -> #DIV/0! | DL37: =DD37 -> 0.4 | DM37: =DM38/DM36 -> #DIV/0! | DN37: 0.4 | DO37: =DO38/DO36 -> #DIV/0! | DP37: =DN37 -> 0.4 | DQ37: =DQ38/DQ36 -> #DIV/0! | DR37: =DN37 -> 0.4 | DS37: =DS38/DS36 -> #DIV/0! | DT37: =DN37 -> 0.4 | DU37: =DU38/DU36 -> #DIV/0! | DV37: =DN37 -> 0.4
C38: Total de reuniões agendadas | D38: =SUM(F38+Q38+AA38+AK38+AU38+BE38+BO38+BY38+CI38+CS38+DC38+DM38) -> 0 | E38: =SUM(G38+R38+AB38+AL38+AV38+BF38+BP38+BZ38+CJ38+CT38+DD38+DN38) -> 0 | F38: =SUM(I38+K38+M38+O38) -> 0 | G38: =G40/G39 -> 0 | H38: =G38/F38 -> #DIV/0! | J38: =G38/4 -> 0 | L38: =G38/4 -> 0 | N38: =G38/4 -> 0 | P38: =G38/4 -> 0 | Q38: =SUM(S38+U38+W38+Y38) -> 0 | R38: =R40/R39 -> 0 | T38: =R38/4 -> 0 | V38: =R38/4 -> 0 | X38: =R38/4 -> 0 | Z38: =R38/4 -> 0 | AA38: =SUM(AC38+AE38+AG38+AI38) -> 0 | AB38: =AB40/AB39 -> 0 | AD38: =AB38/4 -> 0 | AF38: =AB38/4 -> 0 | AH38: =AB38/4 -> 0 | AJ38: =AB38/4 -> 0 | AK38: =SUM(AM38+AO38+AQ38+AS38) -> 0 | AL38: =AL40/AL39 -> 0 | AN38: =AL38/4 -> 0 | AP38: =AL38/4 -> 0 | AR38: =AL38/4 -> 0 | AT38: =AL38/4 -> 0 | AU38: =SUM(AW38+AY38+BA38+BC38) -> 0 | AV38: =AV40/AV39 -> 0 | AX38: =AV38/4 -> 0 | AZ38: =AV38/4 -> 0 | BB38: =AV38/4 -> 0 | BD38: =AV38/4 -> 0 | BE38: =SUM(BG38+BI38+BK38+BM38) -> 0 | BF38: =BF40/BF39 -> 0 | BH38: =BF38/4 -> 0 | BJ38: =BF38/4 -> 0 | BL38: =BF38/4 -> 0 | BN38: =BF38/4 -> 0 | BO38: =SUM(BQ38+BS38+BU38+BW38) -> 0 | BP38: =BP40/BP39 -> 0 | BR38: =BP38/4 -> 0 | BT38: =BP38/4 -> 0 | BV38: =BP38/4 -> 0 | BX38: =BP38/4 -> 0 | BY38: =SUM(CA38+CC38+CE38+CG38) -> 0 | BZ38: =BZ40/BZ39 -> 0 | CB38: =BZ38/4 -> 0 | CD38: =BZ38/4 -> 0 | CF38: =BZ38/4 -> 0 | CH38: =BZ38/4 -> 0 | CI38: =SUM(CK38+CM38+CO38+CQ38) -> 0 | CJ38: =CJ40/CJ39 -> 0 | CL38: =CJ38/4 -> 0 | CN38: =CJ38/4 -> 0 | CP38: =CJ38/4 -> 0 | CR38: =CJ38/4 -> 0 | CS38: =SUM(CU38+CW38+CY38+DA38) -> 0 | CT38: =CT40/CT39 -> 0 | CV38: =CT38/4 -> 0 | CX38: =CT38/4 -> 0 | CZ38: =CT38/4 -> 0 | DB38: =CT38/4 -> 0 | DC38: =SUM(DE38+DG38+DI38+DK38) -> 0 | DD38: =DD40/DD39 -> 0 | DF38: =DD38/4 -> 0 | DH38: =DD38/4 -> 0 | DJ38: =DD38/4 -> 0 | DL38: =DD38/4 -> 0 | DM38: =SUM(DO38+DQ38+DS38+DU38) -> 0 | DN38: =DN40/DN39 -> 0 | DP38: =DN38/4 -> 0 | DR38: =DN38/4 -> 0 | DT38: =DN38/4 -> 0 | DV38: =DN38/4 -> 0
